2017-05-06 14:54:17,134 [Thread-15:-1271923904] [django.request:152] [base:get_response] [WARNING]- Not Found: /favicon.ico
2017-05-06 15:17:38,249 [Thread-2:-1250952384] [django.request:135] [exception:handle_uncaught_exception] [ERROR]- Internal Server Error: /index
Traceback (most recent call last):
  File "/home/ubunturoot/.pyenv/versions/blog/lib/python3.5/site-packages/django/core/handlers/exception.py", line 41, in inner
    response = get_response(request)
TypeError: 'dict' object is not callable
2017-05-06 15:18:07,858 [Thread-2:-1250952384] [django.request:135] [exception:handle_uncaught_exception] [ERROR]- Internal Server Error: /index
Traceback (most recent call last):
  File "/home/ubunturoot/.pyenv/versions/blog/lib/python3.5/site-packages/django/core/handlers/exception.py", line 41, in inner
    response = get_response(request)
TypeError: 'dict' object is not callable
2017-05-06 15:18:50,225 [Thread-2:-1250952384] [django.request:152] [base:get_response] [WARNING]- Not Found: /index
2017-05-06 15:19:29,339 [Thread-2:-1251476672] [django.request:135] [exception:handle_uncaught_exception] [ERROR]- Internal Server Error: /
Traceback (most recent call last):
  File "/home/ubunturoot/.pyenv/versions/blog/lib/python3.5/site-packages/django/core/handlers/exception.py", line 41, in inner
    response = get_response(request)
  File "/home/ubunturoot/.pyenv/versions/blog/lib/python3.5/site-packages/django/core/handlers/base.py", line 187, in _get_response
    response = self.process_exception_by_middleware(e, request)
  File "/home/ubunturoot/.pyenv/versions/blog/lib/python3.5/site-packages/django/core/handlers/base.py", line 185, in _get_response
    response = wrapped_callback(request, *callback_args, **callback_kwargs)
  File "/home/ubunturoot/blog/blog_project/blog/views.py", line 15, in index
    return render(request, 'index.html', locals())
  File "/home/ubunturoot/.pyenv/versions/blog/lib/python3.5/site-packages/django/shortcuts.py", line 30, in render
    content = loader.render_to_string(template_name, context, request, using=using)
  File "/home/ubunturoot/.pyenv/versions/blog/lib/python3.5/site-packages/django/template/loader.py", line 68, in render_to_string
    return template.render(context, request)
  File "/home/ubunturoot/.pyenv/versions/blog/lib/python3.5/site-packages/django/template/backends/django.py", line 66, in render
    return self.template.render(context)
  File "/home/ubunturoot/.pyenv/versions/blog/lib/python3.5/site-packages/django/template/base.py", line 205, in render
    with context.bind_template(self):
  File "/home/ubunturoot/.pyenv/versions/3.5.1/lib/python3.5/contextlib.py", line 59, in __enter__
    return next(self.gen)
  File "/home/ubunturoot/.pyenv/versions/blog/lib/python3.5/site-packages/django/template/context.py", line 263, in bind_template
    updates.update(processor(self.request))
  File "/home/ubunturoot/blog/blog_project/blog/views.py", line 12, in global_settings
    'GITHUb_URL':settings.GITHUb_URL,
  File "/home/ubunturoot/.pyenv/versions/blog/lib/python3.5/site-packages/django/conf/__init__.py", line 57, in __getattr__
    val = getattr(self._wrapped, name)
AttributeError: 'Settings' object has no attribute 'GITHUb_URL'
2017-05-06 15:58:52,630 [Thread-12:-1280316608] [django.request:152] [base:get_response] [WARNING]- Not Found: /favicon.ico
2017-05-07 03:38:59,416 [Thread-13:-1287660736] [django.request:152] [base:get_response] [WARNING]- Not Found: /favicon.ico
2017-05-07 07:28:22,982 [Thread-11:-1261438144] [django.request:152] [base:get_response] [WARNING]- Not Found: /favicon.ico
2017-05-07 08:12:04,527 [Thread-7:-1250952384] [django.request:152] [base:get_response] [WARNING]- Not Found: /index
2017-05-07 08:55:15,863 [Thread-23:-1297102016] [django.request:152] [base:get_response] [WARNING]- Not Found: /uploads/avatar/2017/05/portrait.jpg
2017-05-07 09:44:43,480 [Thread-7:-1280316608] [django.request:152] [base:get_response] [WARNING]- Not Found: /uploads
2017-05-07 09:49:01,843 [Thread-14:-1250952384] [django.request:135] [exception:handle_uncaught_exception] [ERROR]- Internal Server Error: /admin/blog/user/1/change/
Traceback (most recent call last):
  File "/home/ubunturoot/.pyenv/versions/blog/lib/python3.5/site-packages/django/core/handlers/exception.py", line 41, in inner
    response = get_response(request)
  File "/home/ubunturoot/.pyenv/versions/blog/lib/python3.5/site-packages/django/core/handlers/base.py", line 187, in _get_response
    response = self.process_exception_by_middleware(e, request)
  File "/home/ubunturoot/.pyenv/versions/blog/lib/python3.5/site-packages/django/core/handlers/base.py", line 185, in _get_response
    response = wrapped_callback(request, *callback_args, **callback_kwargs)
  File "/home/ubunturoot/.pyenv/versions/blog/lib/python3.5/site-packages/django/contrib/admin/options.py", line 551, in wrapper
    return self.admin_site.admin_view(view)(*args, **kwargs)
  File "/home/ubunturoot/.pyenv/versions/blog/lib/python3.5/site-packages/django/utils/decorators.py", line 149, in _wrapped_view
    response = view_func(request, *args, **kwargs)
  File "/home/ubunturoot/.pyenv/versions/blog/lib/python3.5/site-packages/django/views/decorators/cache.py", line 57, in _wrapped_view_func
    response = view_func(request, *args, **kwargs)
  File "/home/ubunturoot/.pyenv/versions/blog/lib/python3.5/site-packages/django/contrib/admin/sites.py", line 224, in inner
    return view(request, *args, **kwargs)
  File "/home/ubunturoot/.pyenv/versions/blog/lib/python3.5/site-packages/django/contrib/admin/options.py", line 1511, in change_view
    return self.changeform_view(request, object_id, form_url, extra_context)
  File "/home/ubunturoot/.pyenv/versions/blog/lib/python3.5/site-packages/django/utils/decorators.py", line 67, in _wrapper
    return bound_func(*args, **kwargs)
  File "/home/ubunturoot/.pyenv/versions/blog/lib/python3.5/site-packages/django/utils/decorators.py", line 149, in _wrapped_view
    response = view_func(request, *args, **kwargs)
  File "/home/ubunturoot/.pyenv/versions/blog/lib/python3.5/site-packages/django/utils/decorators.py", line 63, in bound_func
    return func.__get__(self, type(self))(*args2, **kwargs2)
  File "/home/ubunturoot/.pyenv/versions/blog/lib/python3.5/site-packages/django/contrib/admin/options.py", line 1408, in changeform_view
    return self._changeform_view(request, object_id, form_url, extra_context)
  File "/home/ubunturoot/.pyenv/versions/blog/lib/python3.5/site-packages/django/contrib/admin/options.py", line 1448, in _changeform_view
    self.save_model(request, new_object, form, not add)
  File "/home/ubunturoot/.pyenv/versions/blog/lib/python3.5/site-packages/django/contrib/admin/options.py", line 979, in save_model
    obj.save()
  File "/home/ubunturoot/.pyenv/versions/blog/lib/python3.5/site-packages/django/contrib/auth/base_user.py", line 80, in save
    super(AbstractBaseUser, self).save(*args, **kwargs)
  File "/home/ubunturoot/.pyenv/versions/blog/lib/python3.5/site-packages/django/db/models/base.py", line 806, in save
    force_update=force_update, update_fields=update_fields)
  File "/home/ubunturoot/.pyenv/versions/blog/lib/python3.5/site-packages/django/db/models/base.py", line 836, in save_base
    updated = self._save_table(raw, cls, force_insert, force_update, using, update_fields)
  File "/home/ubunturoot/.pyenv/versions/blog/lib/python3.5/site-packages/django/db/models/base.py", line 900, in _save_table
    for f in non_pks]
  File "/home/ubunturoot/.pyenv/versions/blog/lib/python3.5/site-packages/django/db/models/base.py", line 900, in <listcomp>
    for f in non_pks]
  File "/home/ubunturoot/.pyenv/versions/blog/lib/python3.5/site-packages/django/db/models/fields/files.py", line 297, in pre_save
    file.save(file.name, file.file, save=False)
  File "/home/ubunturoot/.pyenv/versions/blog/lib/python3.5/site-packages/django/db/models/fields/files.py", line 95, in save
    self.name = self.storage.save(name, content, max_length=self.field.max_length)
  File "/home/ubunturoot/.pyenv/versions/blog/lib/python3.5/site-packages/django/core/files/storage.py", line 53, in save
    name = self.get_available_name(name, max_length=max_length)
  File "/home/ubunturoot/.pyenv/versions/blog/lib/python3.5/site-packages/django/core/files/storage.py", line 77, in get_available_name
    while self.exists(name) or (max_length and len(name) > max_length):
  File "/home/ubunturoot/.pyenv/versions/blog/lib/python3.5/site-packages/django/core/files/storage.py", line 392, in exists
    return os.path.exists(self.path(name))
  File "/home/ubunturoot/.pyenv/versions/blog/lib/python3.5/site-packages/django/core/files/storage.py", line 405, in path
    return safe_join(self.location, name)
  File "/home/ubunturoot/.pyenv/versions/blog/lib/python3.5/site-packages/django/utils/functional.py", line 35, in __get__
    res = instance.__dict__[self.name] = self.func(instance)
  File "/home/ubunturoot/.pyenv/versions/blog/lib/python3.5/site-packages/django/core/files/storage.py", line 283, in location
    return abspathu(self.base_location)
  File "/home/ubunturoot/.pyenv/versions/3.5.1/lib/python3.5/posixpath.py", line 357, in abspath
    if not isabs(path):
  File "/home/ubunturoot/.pyenv/versions/3.5.1/lib/python3.5/posixpath.py", line 64, in isabs
    return s.startswith(sep)
AttributeError: 'list' object has no attribute 'startswith'
2017-05-07 09:50:12,318 [Thread-20:-1271923904] [django.request:135] [exception:handle_uncaught_exception] [ERROR]- Internal Server Error: /admin/blog/user/1/change/
Traceback (most recent call last):
  File "/home/ubunturoot/.pyenv/versions/blog/lib/python3.5/site-packages/django/core/handlers/exception.py", line 41, in inner
    response = get_response(request)
  File "/home/ubunturoot/.pyenv/versions/blog/lib/python3.5/site-packages/django/core/handlers/base.py", line 187, in _get_response
    response = self.process_exception_by_middleware(e, request)
  File "/home/ubunturoot/.pyenv/versions/blog/lib/python3.5/site-packages/django/core/handlers/base.py", line 185, in _get_response
    response = wrapped_callback(request, *callback_args, **callback_kwargs)
  File "/home/ubunturoot/.pyenv/versions/blog/lib/python3.5/site-packages/django/contrib/admin/options.py", line 551, in wrapper
    return self.admin_site.admin_view(view)(*args, **kwargs)
  File "/home/ubunturoot/.pyenv/versions/blog/lib/python3.5/site-packages/django/utils/decorators.py", line 149, in _wrapped_view
    response = view_func(request, *args, **kwargs)
  File "/home/ubunturoot/.pyenv/versions/blog/lib/python3.5/site-packages/django/views/decorators/cache.py", line 57, in _wrapped_view_func
    response = view_func(request, *args, **kwargs)
  File "/home/ubunturoot/.pyenv/versions/blog/lib/python3.5/site-packages/django/contrib/admin/sites.py", line 224, in inner
    return view(request, *args, **kwargs)
  File "/home/ubunturoot/.pyenv/versions/blog/lib/python3.5/site-packages/django/contrib/admin/options.py", line 1511, in change_view
    return self.changeform_view(request, object_id, form_url, extra_context)
  File "/home/ubunturoot/.pyenv/versions/blog/lib/python3.5/site-packages/django/utils/decorators.py", line 67, in _wrapper
    return bound_func(*args, **kwargs)
  File "/home/ubunturoot/.pyenv/versions/blog/lib/python3.5/site-packages/django/utils/decorators.py", line 149, in _wrapped_view
    response = view_func(request, *args, **kwargs)
  File "/home/ubunturoot/.pyenv/versions/blog/lib/python3.5/site-packages/django/utils/decorators.py", line 63, in bound_func
    return func.__get__(self, type(self))(*args2, **kwargs2)
  File "/home/ubunturoot/.pyenv/versions/blog/lib/python3.5/site-packages/django/contrib/admin/options.py", line 1408, in changeform_view
    return self._changeform_view(request, object_id, form_url, extra_context)
  File "/home/ubunturoot/.pyenv/versions/blog/lib/python3.5/site-packages/django/contrib/admin/options.py", line 1448, in _changeform_view
    self.save_model(request, new_object, form, not add)
  File "/home/ubunturoot/.pyenv/versions/blog/lib/python3.5/site-packages/django/contrib/admin/options.py", line 979, in save_model
    obj.save()
  File "/home/ubunturoot/.pyenv/versions/blog/lib/python3.5/site-packages/django/contrib/auth/base_user.py", line 80, in save
    super(AbstractBaseUser, self).save(*args, **kwargs)
  File "/home/ubunturoot/.pyenv/versions/blog/lib/python3.5/site-packages/django/db/models/base.py", line 806, in save
    force_update=force_update, update_fields=update_fields)
  File "/home/ubunturoot/.pyenv/versions/blog/lib/python3.5/site-packages/django/db/models/base.py", line 836, in save_base
    updated = self._save_table(raw, cls, force_insert, force_update, using, update_fields)
  File "/home/ubunturoot/.pyenv/versions/blog/lib/python3.5/site-packages/django/db/models/base.py", line 900, in _save_table
    for f in non_pks]
  File "/home/ubunturoot/.pyenv/versions/blog/lib/python3.5/site-packages/django/db/models/base.py", line 900, in <listcomp>
    for f in non_pks]
  File "/home/ubunturoot/.pyenv/versions/blog/lib/python3.5/site-packages/django/db/models/fields/files.py", line 297, in pre_save
    file.save(file.name, file.file, save=False)
  File "/home/ubunturoot/.pyenv/versions/blog/lib/python3.5/site-packages/django/db/models/fields/files.py", line 95, in save
    self.name = self.storage.save(name, content, max_length=self.field.max_length)
  File "/home/ubunturoot/.pyenv/versions/blog/lib/python3.5/site-packages/django/core/files/storage.py", line 53, in save
    name = self.get_available_name(name, max_length=max_length)
  File "/home/ubunturoot/.pyenv/versions/blog/lib/python3.5/site-packages/django/core/files/storage.py", line 77, in get_available_name
    while self.exists(name) or (max_length and len(name) > max_length):
  File "/home/ubunturoot/.pyenv/versions/blog/lib/python3.5/site-packages/django/core/files/storage.py", line 392, in exists
    return os.path.exists(self.path(name))
  File "/home/ubunturoot/.pyenv/versions/blog/lib/python3.5/site-packages/django/core/files/storage.py", line 405, in path
    return safe_join(self.location, name)
  File "/home/ubunturoot/.pyenv/versions/blog/lib/python3.5/site-packages/django/utils/functional.py", line 35, in __get__
    res = instance.__dict__[self.name] = self.func(instance)
  File "/home/ubunturoot/.pyenv/versions/blog/lib/python3.5/site-packages/django/core/files/storage.py", line 283, in location
    return abspathu(self.base_location)
  File "/home/ubunturoot/.pyenv/versions/3.5.1/lib/python3.5/posixpath.py", line 357, in abspath
    if not isabs(path):
  File "/home/ubunturoot/.pyenv/versions/3.5.1/lib/python3.5/posixpath.py", line 64, in isabs
    return s.startswith(sep)
AttributeError: 'list' object has no attribute 'startswith'
2017-05-07 09:52:55,290 [Thread-38:-1250952384] [django.request:152] [base:get_response] [WARNING]- Not Found: /admin/upload/kindeditor
2017-05-07 09:57:26,393 [Thread-47:-1290798272] [django.request:135] [exception:handle_uncaught_exception] [ERROR]- Internal Server Error: /admin/blog/user/1/change/
Traceback (most recent call last):
  File "/home/ubunturoot/.pyenv/versions/blog/lib/python3.5/site-packages/django/core/handlers/exception.py", line 41, in inner
    response = get_response(request)
  File "/home/ubunturoot/.pyenv/versions/blog/lib/python3.5/site-packages/django/core/handlers/base.py", line 187, in _get_response
    response = self.process_exception_by_middleware(e, request)
  File "/home/ubunturoot/.pyenv/versions/blog/lib/python3.5/site-packages/django/core/handlers/base.py", line 185, in _get_response
    response = wrapped_callback(request, *callback_args, **callback_kwargs)
  File "/home/ubunturoot/.pyenv/versions/blog/lib/python3.5/site-packages/django/contrib/admin/options.py", line 551, in wrapper
    return self.admin_site.admin_view(view)(*args, **kwargs)
  File "/home/ubunturoot/.pyenv/versions/blog/lib/python3.5/site-packages/django/utils/decorators.py", line 149, in _wrapped_view
    response = view_func(request, *args, **kwargs)
  File "/home/ubunturoot/.pyenv/versions/blog/lib/python3.5/site-packages/django/views/decorators/cache.py", line 57, in _wrapped_view_func
    response = view_func(request, *args, **kwargs)
  File "/home/ubunturoot/.pyenv/versions/blog/lib/python3.5/site-packages/django/contrib/admin/sites.py", line 224, in inner
    return view(request, *args, **kwargs)
  File "/home/ubunturoot/.pyenv/versions/blog/lib/python3.5/site-packages/django/contrib/admin/options.py", line 1511, in change_view
    return self.changeform_view(request, object_id, form_url, extra_context)
  File "/home/ubunturoot/.pyenv/versions/blog/lib/python3.5/site-packages/django/utils/decorators.py", line 67, in _wrapper
    return bound_func(*args, **kwargs)
  File "/home/ubunturoot/.pyenv/versions/blog/lib/python3.5/site-packages/django/utils/decorators.py", line 149, in _wrapped_view
    response = view_func(request, *args, **kwargs)
  File "/home/ubunturoot/.pyenv/versions/blog/lib/python3.5/site-packages/django/utils/decorators.py", line 63, in bound_func
    return func.__get__(self, type(self))(*args2, **kwargs2)
  File "/home/ubunturoot/.pyenv/versions/blog/lib/python3.5/site-packages/django/contrib/admin/options.py", line 1408, in changeform_view
    return self._changeform_view(request, object_id, form_url, extra_context)
  File "/home/ubunturoot/.pyenv/versions/blog/lib/python3.5/site-packages/django/contrib/admin/options.py", line 1448, in _changeform_view
    self.save_model(request, new_object, form, not add)
  File "/home/ubunturoot/.pyenv/versions/blog/lib/python3.5/site-packages/django/contrib/admin/options.py", line 979, in save_model
    obj.save()
  File "/home/ubunturoot/.pyenv/versions/blog/lib/python3.5/site-packages/django/contrib/auth/base_user.py", line 80, in save
    super(AbstractBaseUser, self).save(*args, **kwargs)
  File "/home/ubunturoot/.pyenv/versions/blog/lib/python3.5/site-packages/django/db/models/base.py", line 806, in save
    force_update=force_update, update_fields=update_fields)
  File "/home/ubunturoot/.pyenv/versions/blog/lib/python3.5/site-packages/django/db/models/base.py", line 836, in save_base
    updated = self._save_table(raw, cls, force_insert, force_update, using, update_fields)
  File "/home/ubunturoot/.pyenv/versions/blog/lib/python3.5/site-packages/django/db/models/base.py", line 900, in _save_table
    for f in non_pks]
  File "/home/ubunturoot/.pyenv/versions/blog/lib/python3.5/site-packages/django/db/models/base.py", line 900, in <listcomp>
    for f in non_pks]
  File "/home/ubunturoot/.pyenv/versions/blog/lib/python3.5/site-packages/django/db/models/fields/files.py", line 297, in pre_save
    file.save(file.name, file.file, save=False)
  File "/home/ubunturoot/.pyenv/versions/blog/lib/python3.5/site-packages/django/db/models/fields/files.py", line 95, in save
    self.name = self.storage.save(name, content, max_length=self.field.max_length)
  File "/home/ubunturoot/.pyenv/versions/blog/lib/python3.5/site-packages/django/core/files/storage.py", line 53, in save
    name = self.get_available_name(name, max_length=max_length)
  File "/home/ubunturoot/.pyenv/versions/blog/lib/python3.5/site-packages/django/core/files/storage.py", line 77, in get_available_name
    while self.exists(name) or (max_length and len(name) > max_length):
  File "/home/ubunturoot/.pyenv/versions/blog/lib/python3.5/site-packages/django/core/files/storage.py", line 392, in exists
    return os.path.exists(self.path(name))
  File "/home/ubunturoot/.pyenv/versions/blog/lib/python3.5/site-packages/django/core/files/storage.py", line 405, in path
    return safe_join(self.location, name)
  File "/home/ubunturoot/.pyenv/versions/blog/lib/python3.5/site-packages/django/utils/functional.py", line 35, in __get__
    res = instance.__dict__[self.name] = self.func(instance)
  File "/home/ubunturoot/.pyenv/versions/blog/lib/python3.5/site-packages/django/core/files/storage.py", line 283, in location
    return abspathu(self.base_location)
  File "/home/ubunturoot/.pyenv/versions/3.5.1/lib/python3.5/posixpath.py", line 357, in abspath
    if not isabs(path):
  File "/home/ubunturoot/.pyenv/versions/3.5.1/lib/python3.5/posixpath.py", line 64, in isabs
    return s.startswith(sep)
AttributeError: 'list' object has no attribute 'startswith'
2017-05-07 15:20:23,068 [Thread-5:-1279268032] [django.request:152] [base:get_response] [WARNING]- Not Found: /favicon.ico
2017-05-07 15:38:17,515 [Thread-2:-1250952384] [django.request:135] [exception:handle_uncaught_exception] [ERROR]- Internal Server Error: /
Traceback (most recent call last):
  File "/home/ubunturoot/.pyenv/versions/blog/lib/python3.5/site-packages/django/core/handlers/exception.py", line 41, in inner
    response = get_response(request)
  File "/home/ubunturoot/.pyenv/versions/blog/lib/python3.5/site-packages/django/core/handlers/base.py", line 187, in _get_response
    response = self.process_exception_by_middleware(e, request)
  File "/home/ubunturoot/.pyenv/versions/blog/lib/python3.5/site-packages/django/core/handlers/base.py", line 185, in _get_response
    response = wrapped_callback(request, *callback_args, **callback_kwargs)
  File "/home/ubunturoot/blog/blog_project/blog/views.py", line 20, in index
    return render(request, 'index.html', {'category_list':category_list})
  File "/home/ubunturoot/.pyenv/versions/blog/lib/python3.5/site-packages/django/shortcuts.py", line 30, in render
    content = loader.render_to_string(template_name, context, request, using=using)
  File "/home/ubunturoot/.pyenv/versions/blog/lib/python3.5/site-packages/django/template/loader.py", line 68, in render_to_string
    return template.render(context, request)
  File "/home/ubunturoot/.pyenv/versions/blog/lib/python3.5/site-packages/django/template/backends/django.py", line 66, in render
    return self.template.render(context)
  File "/home/ubunturoot/.pyenv/versions/blog/lib/python3.5/site-packages/django/template/base.py", line 207, in render
    return self._render(context)
  File "/home/ubunturoot/.pyenv/versions/blog/lib/python3.5/site-packages/django/template/base.py", line 199, in _render
    return self.nodelist.render(context)
  File "/home/ubunturoot/.pyenv/versions/blog/lib/python3.5/site-packages/django/template/base.py", line 990, in render
    bit = node.render_annotated(context)
  File "/home/ubunturoot/.pyenv/versions/blog/lib/python3.5/site-packages/django/template/base.py", line 957, in render_annotated
    return self.render(context)
  File "/home/ubunturoot/.pyenv/versions/blog/lib/python3.5/site-packages/django/template/loader_tags.py", line 177, in render
    return compiled_parent._render(context)
  File "/home/ubunturoot/.pyenv/versions/blog/lib/python3.5/site-packages/django/template/base.py", line 199, in _render
    return self.nodelist.render(context)
  File "/home/ubunturoot/.pyenv/versions/blog/lib/python3.5/site-packages/django/template/base.py", line 990, in render
    bit = node.render_annotated(context)
  File "/home/ubunturoot/.pyenv/versions/blog/lib/python3.5/site-packages/django/template/base.py", line 957, in render_annotated
    return self.render(context)
  File "/home/ubunturoot/.pyenv/versions/blog/lib/python3.5/site-packages/django/template/defaulttags.py", line 216, in render
    nodelist.append(node.render_annotated(context))
  File "/home/ubunturoot/.pyenv/versions/blog/lib/python3.5/site-packages/django/template/base.py", line 957, in render_annotated
    return self.render(context)
  File "/home/ubunturoot/.pyenv/versions/blog/lib/python3.5/site-packages/django/template/defaulttags.py", line 458, in render
    url = reverse(view_name, args=args, kwargs=kwargs, current_app=current_app)
  File "/home/ubunturoot/.pyenv/versions/blog/lib/python3.5/site-packages/django/urls/base.py", line 91, in reverse
    return force_text(iri_to_uri(resolver._reverse_with_prefix(view, prefix, *args, **kwargs)))
  File "/home/ubunturoot/.pyenv/versions/blog/lib/python3.5/site-packages/django/urls/resolvers.py", line 497, in _reverse_with_prefix
    raise NoReverseMatch(msg)
django.urls.exceptions.NoReverseMatch: Reverse for 'category' not found. 'category' is not a valid view function or pattern name.
2017-05-10 07:19:33,218 [Thread-2:-1250690240] [django.request:135] [exception:handle_uncaught_exception] [ERROR]- Internal Server Error: /
Traceback (most recent call last):
  File "/home/ubunturoot/.pyenv/versions/blog/lib/python3.5/site-packages/django/core/handlers/exception.py", line 41, in inner
    response = get_response(request)
  File "/home/ubunturoot/.pyenv/versions/blog/lib/python3.5/site-packages/django/core/handlers/base.py", line 187, in _get_response
    response = self.process_exception_by_middleware(e, request)
  File "/home/ubunturoot/.pyenv/versions/blog/lib/python3.5/site-packages/django/core/handlers/base.py", line 185, in _get_response
    response = wrapped_callback(request, *callback_args, **callback_kwargs)
  File "/home/ubunturoot/blog/blog_project/blog/views.py", line 20, in index
    return render(request, 'index.html', {'category_list':category_list})
  File "/home/ubunturoot/.pyenv/versions/blog/lib/python3.5/site-packages/django/shortcuts.py", line 30, in render
    content = loader.render_to_string(template_name, context, request, using=using)
  File "/home/ubunturoot/.pyenv/versions/blog/lib/python3.5/site-packages/django/template/loader.py", line 68, in render_to_string
    return template.render(context, request)
  File "/home/ubunturoot/.pyenv/versions/blog/lib/python3.5/site-packages/django/template/backends/django.py", line 66, in render
    return self.template.render(context)
  File "/home/ubunturoot/.pyenv/versions/blog/lib/python3.5/site-packages/django/template/base.py", line 207, in render
    return self._render(context)
  File "/home/ubunturoot/.pyenv/versions/blog/lib/python3.5/site-packages/django/template/base.py", line 199, in _render
    return self.nodelist.render(context)
  File "/home/ubunturoot/.pyenv/versions/blog/lib/python3.5/site-packages/django/template/base.py", line 990, in render
    bit = node.render_annotated(context)
  File "/home/ubunturoot/.pyenv/versions/blog/lib/python3.5/site-packages/django/template/base.py", line 957, in render_annotated
    return self.render(context)
  File "/home/ubunturoot/.pyenv/versions/blog/lib/python3.5/site-packages/django/template/loader_tags.py", line 177, in render
    return compiled_parent._render(context)
  File "/home/ubunturoot/.pyenv/versions/blog/lib/python3.5/site-packages/django/template/base.py", line 199, in _render
    return self.nodelist.render(context)
  File "/home/ubunturoot/.pyenv/versions/blog/lib/python3.5/site-packages/django/template/base.py", line 990, in render
    bit = node.render_annotated(context)
  File "/home/ubunturoot/.pyenv/versions/blog/lib/python3.5/site-packages/django/template/base.py", line 957, in render_annotated
    return self.render(context)
  File "/home/ubunturoot/.pyenv/versions/blog/lib/python3.5/site-packages/django/template/defaulttags.py", line 216, in render
    nodelist.append(node.render_annotated(context))
  File "/home/ubunturoot/.pyenv/versions/blog/lib/python3.5/site-packages/django/template/base.py", line 957, in render_annotated
    return self.render(context)
  File "/home/ubunturoot/.pyenv/versions/blog/lib/python3.5/site-packages/django/template/defaulttags.py", line 458, in render
    url = reverse(view_name, args=args, kwargs=kwargs, current_app=current_app)
  File "/home/ubunturoot/.pyenv/versions/blog/lib/python3.5/site-packages/django/urls/base.py", line 91, in reverse
    return force_text(iri_to_uri(resolver._reverse_with_prefix(view, prefix, *args, **kwargs)))
  File "/home/ubunturoot/.pyenv/versions/blog/lib/python3.5/site-packages/django/urls/resolvers.py", line 497, in _reverse_with_prefix
    raise NoReverseMatch(msg)
django.urls.exceptions.NoReverseMatch: Reverse for 'category' not found. 'category' is not a valid view function or pattern name.
2017-05-10 07:19:34,580 [Thread-3:-1260389568] [django.request:152] [base:get_response] [WARNING]- Not Found: /favicon.ico
2017-05-10 08:56:33,901 [Thread-2:-1250952384] [django.request:135] [exception:handle_uncaught_exception] [ERROR]- Internal Server Error: /
Traceback (most recent call last):
  File "/home/ubunturoot/.pyenv/versions/blog/lib/python3.5/site-packages/django/core/handlers/exception.py", line 41, in inner
    response = get_response(request)
  File "/home/ubunturoot/.pyenv/versions/blog/lib/python3.5/site-packages/django/core/handlers/base.py", line 187, in _get_response
    response = self.process_exception_by_middleware(e, request)
  File "/home/ubunturoot/.pyenv/versions/blog/lib/python3.5/site-packages/django/core/handlers/base.py", line 185, in _get_response
    response = wrapped_callback(request, *callback_args, **callback_kwargs)
  File "/home/ubunturoot/blog/blog_project/blog/views.py", line 24, in index
    article_list = paginator.page(page)
NameError: name 'paginator' is not defined
2017-05-10 08:58:01,347 [Thread-2:-1250952384] [django.request:135] [exception:handle_uncaught_exception] [ERROR]- Internal Server Error: /
Traceback (most recent call last):
  File "/home/ubunturoot/.pyenv/versions/blog/lib/python3.5/site-packages/django/core/handlers/exception.py", line 41, in inner
    response = get_response(request)
  File "/home/ubunturoot/.pyenv/versions/blog/lib/python3.5/site-packages/django/core/handlers/base.py", line 187, in _get_response
    response = self.process_exception_by_middleware(e, request)
  File "/home/ubunturoot/.pyenv/versions/blog/lib/python3.5/site-packages/django/core/handlers/base.py", line 185, in _get_response
    response = wrapped_callback(request, *callback_args, **callback_kwargs)
  File "/home/ubunturoot/blog/blog_project/blog/views.py", line 24, in index
    article_list = Paginator.page(page)
TypeError: page() missing 1 required positional argument: 'number'
2017-05-10 09:08:43,144 [Thread-2:-1251214528] [django.request:135] [exception:handle_uncaught_exception] [ERROR]- Internal Server Error: /
Traceback (most recent call last):
  File "/home/ubunturoot/.pyenv/versions/blog/lib/python3.5/site-packages/django/core/handlers/exception.py", line 41, in inner
    response = get_response(request)
  File "/home/ubunturoot/.pyenv/versions/blog/lib/python3.5/site-packages/django/core/handlers/base.py", line 187, in _get_response
    response = self.process_exception_by_middleware(e, request)
  File "/home/ubunturoot/.pyenv/versions/blog/lib/python3.5/site-packages/django/core/handlers/base.py", line 185, in _get_response
    response = wrapped_callback(request, *callback_args, **callback_kwargs)
  File "/home/ubunturoot/blog/blog_project/blog/views.py", line 23, in index
    paginator = Paginator(Article.objects.all())
NameError: name 'Article' is not defined
2017-05-10 09:08:58,524 [Thread-2:-1250952384] [django.request:135] [exception:handle_uncaught_exception] [ERROR]- Internal Server Error: /
Traceback (most recent call last):
  File "/home/ubunturoot/.pyenv/versions/blog/lib/python3.5/site-packages/django/core/handlers/exception.py", line 41, in inner
    response = get_response(request)
  File "/home/ubunturoot/.pyenv/versions/blog/lib/python3.5/site-packages/django/core/handlers/base.py", line 187, in _get_response
    response = self.process_exception_by_middleware(e, request)
  File "/home/ubunturoot/.pyenv/versions/blog/lib/python3.5/site-packages/django/core/handlers/base.py", line 185, in _get_response
    response = wrapped_callback(request, *callback_args, **callback_kwargs)
  File "/home/ubunturoot/blog/blog_project/blog/views.py", line 23, in index
    paginator = Paginator(Article.objects.all())
TypeError: __init__() missing 1 required positional argument: 'per_page'
2017-05-10 09:11:46,859 [Thread-2:-1251214528] [django.request:135] [exception:handle_uncaught_exception] [ERROR]- Internal Server Error: /
Traceback (most recent call last):
  File "/home/ubunturoot/.pyenv/versions/blog/lib/python3.5/site-packages/django/core/handlers/exception.py", line 41, in inner
    response = get_response(request)
  File "/home/ubunturoot/.pyenv/versions/blog/lib/python3.5/site-packages/django/core/handlers/base.py", line 187, in _get_response
    response = self.process_exception_by_middleware(e, request)
  File "/home/ubunturoot/.pyenv/versions/blog/lib/python3.5/site-packages/django/core/handlers/base.py", line 185, in _get_response
    response = wrapped_callback(request, *callback_args, **callback_kwargs)
  File "/home/ubunturoot/blog/blog_project/blog/views.py", line 31, in index
    return render(request, 'index.html', locals())
  File "/home/ubunturoot/.pyenv/versions/blog/lib/python3.5/site-packages/django/shortcuts.py", line 30, in render
    content = loader.render_to_string(template_name, context, request, using=using)
  File "/home/ubunturoot/.pyenv/versions/blog/lib/python3.5/site-packages/django/template/loader.py", line 68, in render_to_string
    return template.render(context, request)
  File "/home/ubunturoot/.pyenv/versions/blog/lib/python3.5/site-packages/django/template/backends/django.py", line 66, in render
    return self.template.render(context)
  File "/home/ubunturoot/.pyenv/versions/blog/lib/python3.5/site-packages/django/template/base.py", line 207, in render
    return self._render(context)
  File "/home/ubunturoot/.pyenv/versions/blog/lib/python3.5/site-packages/django/template/base.py", line 199, in _render
    return self.nodelist.render(context)
  File "/home/ubunturoot/.pyenv/versions/blog/lib/python3.5/site-packages/django/template/base.py", line 990, in render
    bit = node.render_annotated(context)
  File "/home/ubunturoot/.pyenv/versions/blog/lib/python3.5/site-packages/django/template/base.py", line 957, in render_annotated
    return self.render(context)
  File "/home/ubunturoot/.pyenv/versions/blog/lib/python3.5/site-packages/django/template/loader_tags.py", line 177, in render
    return compiled_parent._render(context)
  File "/home/ubunturoot/.pyenv/versions/blog/lib/python3.5/site-packages/django/template/base.py", line 199, in _render
    return self.nodelist.render(context)
  File "/home/ubunturoot/.pyenv/versions/blog/lib/python3.5/site-packages/django/template/base.py", line 990, in render
    bit = node.render_annotated(context)
  File "/home/ubunturoot/.pyenv/versions/blog/lib/python3.5/site-packages/django/template/base.py", line 957, in render_annotated
    return self.render(context)
  File "/home/ubunturoot/.pyenv/versions/blog/lib/python3.5/site-packages/django/template/defaulttags.py", line 216, in render
    nodelist.append(node.render_annotated(context))
  File "/home/ubunturoot/.pyenv/versions/blog/lib/python3.5/site-packages/django/template/base.py", line 957, in render_annotated
    return self.render(context)
  File "/home/ubunturoot/.pyenv/versions/blog/lib/python3.5/site-packages/django/template/defaulttags.py", line 458, in render
    url = reverse(view_name, args=args, kwargs=kwargs, current_app=current_app)
  File "/home/ubunturoot/.pyenv/versions/blog/lib/python3.5/site-packages/django/urls/base.py", line 91, in reverse
    return force_text(iri_to_uri(resolver._reverse_with_prefix(view, prefix, *args, **kwargs)))
  File "/home/ubunturoot/.pyenv/versions/blog/lib/python3.5/site-packages/django/urls/resolvers.py", line 497, in _reverse_with_prefix
    raise NoReverseMatch(msg)
django.urls.exceptions.NoReverseMatch: Reverse for 'category' not found. 'category' is not a valid view function or pattern name.
2017-05-10 11:07:09,217 [Thread-3:-1251214528] [django.request:135] [exception:handle_uncaught_exception] [ERROR]- Internal Server Error: /
Traceback (most recent call last):
  File "/home/ubunturoot/.pyenv/versions/blog/lib/python3.5/site-packages/django/core/handlers/exception.py", line 41, in inner
    response = get_response(request)
  File "/home/ubunturoot/.pyenv/versions/blog/lib/python3.5/site-packages/django/core/handlers/base.py", line 187, in _get_response
    response = self.process_exception_by_middleware(e, request)
  File "/home/ubunturoot/.pyenv/versions/blog/lib/python3.5/site-packages/django/core/handlers/base.py", line 185, in _get_response
    response = wrapped_callback(request, *callback_args, **callback_kwargs)
  File "/home/ubunturoot/blog/blog_project/blog/views.py", line 31, in index
    return render(request, 'index.html', locals())
  File "/home/ubunturoot/.pyenv/versions/blog/lib/python3.5/site-packages/django/shortcuts.py", line 30, in render
    content = loader.render_to_string(template_name, context, request, using=using)
  File "/home/ubunturoot/.pyenv/versions/blog/lib/python3.5/site-packages/django/template/loader.py", line 68, in render_to_string
    return template.render(context, request)
  File "/home/ubunturoot/.pyenv/versions/blog/lib/python3.5/site-packages/django/template/backends/django.py", line 66, in render
    return self.template.render(context)
  File "/home/ubunturoot/.pyenv/versions/blog/lib/python3.5/site-packages/django/template/base.py", line 207, in render
    return self._render(context)
  File "/home/ubunturoot/.pyenv/versions/blog/lib/python3.5/site-packages/django/template/base.py", line 199, in _render
    return self.nodelist.render(context)
  File "/home/ubunturoot/.pyenv/versions/blog/lib/python3.5/site-packages/django/template/base.py", line 990, in render
    bit = node.render_annotated(context)
  File "/home/ubunturoot/.pyenv/versions/blog/lib/python3.5/site-packages/django/template/base.py", line 957, in render_annotated
    return self.render(context)
  File "/home/ubunturoot/.pyenv/versions/blog/lib/python3.5/site-packages/django/template/loader_tags.py", line 177, in render
    return compiled_parent._render(context)
  File "/home/ubunturoot/.pyenv/versions/blog/lib/python3.5/site-packages/django/template/base.py", line 199, in _render
    return self.nodelist.render(context)
  File "/home/ubunturoot/.pyenv/versions/blog/lib/python3.5/site-packages/django/template/base.py", line 990, in render
    bit = node.render_annotated(context)
  File "/home/ubunturoot/.pyenv/versions/blog/lib/python3.5/site-packages/django/template/base.py", line 957, in render_annotated
    return self.render(context)
  File "/home/ubunturoot/.pyenv/versions/blog/lib/python3.5/site-packages/django/template/defaulttags.py", line 216, in render
    nodelist.append(node.render_annotated(context))
  File "/home/ubunturoot/.pyenv/versions/blog/lib/python3.5/site-packages/django/template/base.py", line 957, in render_annotated
    return self.render(context)
  File "/home/ubunturoot/.pyenv/versions/blog/lib/python3.5/site-packages/django/template/defaulttags.py", line 458, in render
    url = reverse(view_name, args=args, kwargs=kwargs, current_app=current_app)
  File "/home/ubunturoot/.pyenv/versions/blog/lib/python3.5/site-packages/django/urls/base.py", line 91, in reverse
    return force_text(iri_to_uri(resolver._reverse_with_prefix(view, prefix, *args, **kwargs)))
  File "/home/ubunturoot/.pyenv/versions/blog/lib/python3.5/site-packages/django/urls/resolvers.py", line 497, in _reverse_with_prefix
    raise NoReverseMatch(msg)
django.urls.exceptions.NoReverseMatch: Reverse for 'category' not found. 'category' is not a valid view function or pattern name.
2017-05-10 13:41:26,158 [Thread-2:-1251214528] [django.request:135] [exception:handle_uncaught_exception] [ERROR]- Internal Server Error: /
Traceback (most recent call last):
  File "/home/ubunturoot/.pyenv/versions/blog/lib/python3.5/site-packages/django/core/handlers/exception.py", line 41, in inner
    response = get_response(request)
  File "/home/ubunturoot/.pyenv/versions/blog/lib/python3.5/site-packages/django/core/handlers/base.py", line 187, in _get_response
    response = self.process_exception_by_middleware(e, request)
  File "/home/ubunturoot/.pyenv/versions/blog/lib/python3.5/site-packages/django/core/handlers/base.py", line 185, in _get_response
    response = wrapped_callback(request, *callback_args, **callback_kwargs)
  File "/home/ubunturoot/blog/blog_project/blog/views.py", line 29, in index
    return render(request, 'index.html', locals())
  File "/home/ubunturoot/.pyenv/versions/blog/lib/python3.5/site-packages/django/shortcuts.py", line 30, in render
    content = loader.render_to_string(template_name, context, request, using=using)
  File "/home/ubunturoot/.pyenv/versions/blog/lib/python3.5/site-packages/django/template/loader.py", line 68, in render_to_string
    return template.render(context, request)
  File "/home/ubunturoot/.pyenv/versions/blog/lib/python3.5/site-packages/django/template/backends/django.py", line 66, in render
    return self.template.render(context)
  File "/home/ubunturoot/.pyenv/versions/blog/lib/python3.5/site-packages/django/template/base.py", line 207, in render
    return self._render(context)
  File "/home/ubunturoot/.pyenv/versions/blog/lib/python3.5/site-packages/django/template/base.py", line 199, in _render
    return self.nodelist.render(context)
  File "/home/ubunturoot/.pyenv/versions/blog/lib/python3.5/site-packages/django/template/base.py", line 990, in render
    bit = node.render_annotated(context)
  File "/home/ubunturoot/.pyenv/versions/blog/lib/python3.5/site-packages/django/template/base.py", line 957, in render_annotated
    return self.render(context)
  File "/home/ubunturoot/.pyenv/versions/blog/lib/python3.5/site-packages/django/template/loader_tags.py", line 177, in render
    return compiled_parent._render(context)
  File "/home/ubunturoot/.pyenv/versions/blog/lib/python3.5/site-packages/django/template/base.py", line 199, in _render
    return self.nodelist.render(context)
  File "/home/ubunturoot/.pyenv/versions/blog/lib/python3.5/site-packages/django/template/base.py", line 990, in render
    bit = node.render_annotated(context)
  File "/home/ubunturoot/.pyenv/versions/blog/lib/python3.5/site-packages/django/template/base.py", line 957, in render_annotated
    return self.render(context)
  File "/home/ubunturoot/.pyenv/versions/blog/lib/python3.5/site-packages/django/template/loader_tags.py", line 72, in render
    result = block.nodelist.render(context)
  File "/home/ubunturoot/.pyenv/versions/blog/lib/python3.5/site-packages/django/template/base.py", line 990, in render
    bit = node.render_annotated(context)
  File "/home/ubunturoot/.pyenv/versions/blog/lib/python3.5/site-packages/django/template/base.py", line 957, in render_annotated
    return self.render(context)
  File "/home/ubunturoot/.pyenv/versions/blog/lib/python3.5/site-packages/django/template/defaulttags.py", line 216, in render
    nodelist.append(node.render_annotated(context))
  File "/home/ubunturoot/.pyenv/versions/blog/lib/python3.5/site-packages/django/template/base.py", line 957, in render_annotated
    return self.render(context)
  File "/home/ubunturoot/.pyenv/versions/blog/lib/python3.5/site-packages/django/template/defaulttags.py", line 458, in render
    url = reverse(view_name, args=args, kwargs=kwargs, current_app=current_app)
  File "/home/ubunturoot/.pyenv/versions/blog/lib/python3.5/site-packages/django/urls/base.py", line 91, in reverse
    return force_text(iri_to_uri(resolver._reverse_with_prefix(view, prefix, *args, **kwargs)))
  File "/home/ubunturoot/.pyenv/versions/blog/lib/python3.5/site-packages/django/urls/resolvers.py", line 497, in _reverse_with_prefix
    raise NoReverseMatch(msg)
django.urls.exceptions.NoReverseMatch: Reverse for 'article' not found. 'article' is not a valid view function or pattern name.
2017-05-10 13:41:27,164 [Thread-3:-1251214528] [django.request:152] [base:get_response] [WARNING]- Not Found: /favicon.ico
2017-05-10 13:42:30,752 [Thread-2:-1250952384] [django.request:135] [exception:handle_uncaught_exception] [ERROR]- Internal Server Error: /
Traceback (most recent call last):
  File "/home/ubunturoot/.pyenv/versions/blog/lib/python3.5/site-packages/django/core/handlers/exception.py", line 41, in inner
    response = get_response(request)
  File "/home/ubunturoot/.pyenv/versions/blog/lib/python3.5/site-packages/django/core/handlers/base.py", line 187, in _get_response
    response = self.process_exception_by_middleware(e, request)
  File "/home/ubunturoot/.pyenv/versions/blog/lib/python3.5/site-packages/django/core/handlers/base.py", line 185, in _get_response
    response = wrapped_callback(request, *callback_args, **callback_kwargs)
  File "/home/ubunturoot/blog/blog_project/blog/views.py", line 29, in index
    return render(request, 'index.html', locals())
  File "/home/ubunturoot/.pyenv/versions/blog/lib/python3.5/site-packages/django/shortcuts.py", line 30, in render
    content = loader.render_to_string(template_name, context, request, using=using)
  File "/home/ubunturoot/.pyenv/versions/blog/lib/python3.5/site-packages/django/template/loader.py", line 68, in render_to_string
    return template.render(context, request)
  File "/home/ubunturoot/.pyenv/versions/blog/lib/python3.5/site-packages/django/template/backends/django.py", line 66, in render
    return self.template.render(context)
  File "/home/ubunturoot/.pyenv/versions/blog/lib/python3.5/site-packages/django/template/base.py", line 207, in render
    return self._render(context)
  File "/home/ubunturoot/.pyenv/versions/blog/lib/python3.5/site-packages/django/template/base.py", line 199, in _render
    return self.nodelist.render(context)
  File "/home/ubunturoot/.pyenv/versions/blog/lib/python3.5/site-packages/django/template/base.py", line 990, in render
    bit = node.render_annotated(context)
  File "/home/ubunturoot/.pyenv/versions/blog/lib/python3.5/site-packages/django/template/base.py", line 957, in render_annotated
    return self.render(context)
  File "/home/ubunturoot/.pyenv/versions/blog/lib/python3.5/site-packages/django/template/loader_tags.py", line 177, in render
    return compiled_parent._render(context)
  File "/home/ubunturoot/.pyenv/versions/blog/lib/python3.5/site-packages/django/template/base.py", line 199, in _render
    return self.nodelist.render(context)
  File "/home/ubunturoot/.pyenv/versions/blog/lib/python3.5/site-packages/django/template/base.py", line 990, in render
    bit = node.render_annotated(context)
  File "/home/ubunturoot/.pyenv/versions/blog/lib/python3.5/site-packages/django/template/base.py", line 957, in render_annotated
    return self.render(context)
  File "/home/ubunturoot/.pyenv/versions/blog/lib/python3.5/site-packages/django/template/loader_tags.py", line 72, in render
    result = block.nodelist.render(context)
  File "/home/ubunturoot/.pyenv/versions/blog/lib/python3.5/site-packages/django/template/base.py", line 990, in render
    bit = node.render_annotated(context)
  File "/home/ubunturoot/.pyenv/versions/blog/lib/python3.5/site-packages/django/template/base.py", line 957, in render_annotated
    return self.render(context)
  File "/home/ubunturoot/.pyenv/versions/blog/lib/python3.5/site-packages/django/template/defaulttags.py", line 216, in render
    nodelist.append(node.render_annotated(context))
  File "/home/ubunturoot/.pyenv/versions/blog/lib/python3.5/site-packages/django/template/base.py", line 957, in render_annotated
    return self.render(context)
  File "/home/ubunturoot/.pyenv/versions/blog/lib/python3.5/site-packages/django/template/defaulttags.py", line 458, in render
    url = reverse(view_name, args=args, kwargs=kwargs, current_app=current_app)
  File "/home/ubunturoot/.pyenv/versions/blog/lib/python3.5/site-packages/django/urls/base.py", line 91, in reverse
    return force_text(iri_to_uri(resolver._reverse_with_prefix(view, prefix, *args, **kwargs)))
  File "/home/ubunturoot/.pyenv/versions/blog/lib/python3.5/site-packages/django/urls/resolvers.py", line 497, in _reverse_with_prefix
    raise NoReverseMatch(msg)
django.urls.exceptions.NoReverseMatch: Reverse for 'article' not found. 'article' is not a valid view function or pattern name.
2017-05-10 13:49:11,086 [Thread-12:-1288709312] [django.request:152] [base:get_response] [WARNING]- Not Found: /archive
2017-05-10 13:52:37,054 [Thread-7:-1271923904] [django.request:135] [exception:handle_uncaught_exception] [ERROR]- Internal Server Error: /
Traceback (most recent call last):
  File "/home/ubunturoot/.pyenv/versions/blog/lib/python3.5/site-packages/django/core/handlers/exception.py", line 41, in inner
    response = get_response(request)
  File "/home/ubunturoot/.pyenv/versions/blog/lib/python3.5/site-packages/django/core/handlers/base.py", line 187, in _get_response
    response = self.process_exception_by_middleware(e, request)
  File "/home/ubunturoot/.pyenv/versions/blog/lib/python3.5/site-packages/django/core/handlers/base.py", line 185, in _get_response
    response = wrapped_callback(request, *callback_args, **callback_kwargs)
  File "/home/ubunturoot/blog/blog_project/blog/views.py", line 29, in index
    return render(request, 'index.html', locals())
  File "/home/ubunturoot/.pyenv/versions/blog/lib/python3.5/site-packages/django/shortcuts.py", line 30, in render
    content = loader.render_to_string(template_name, context, request, using=using)
  File "/home/ubunturoot/.pyenv/versions/blog/lib/python3.5/site-packages/django/template/loader.py", line 68, in render_to_string
    return template.render(context, request)
  File "/home/ubunturoot/.pyenv/versions/blog/lib/python3.5/site-packages/django/template/backends/django.py", line 66, in render
    return self.template.render(context)
  File "/home/ubunturoot/.pyenv/versions/blog/lib/python3.5/site-packages/django/template/base.py", line 207, in render
    return self._render(context)
  File "/home/ubunturoot/.pyenv/versions/blog/lib/python3.5/site-packages/django/template/base.py", line 199, in _render
    return self.nodelist.render(context)
  File "/home/ubunturoot/.pyenv/versions/blog/lib/python3.5/site-packages/django/template/base.py", line 990, in render
    bit = node.render_annotated(context)
  File "/home/ubunturoot/.pyenv/versions/blog/lib/python3.5/site-packages/django/template/base.py", line 957, in render_annotated
    return self.render(context)
  File "/home/ubunturoot/.pyenv/versions/blog/lib/python3.5/site-packages/django/template/loader_tags.py", line 177, in render
    return compiled_parent._render(context)
  File "/home/ubunturoot/.pyenv/versions/blog/lib/python3.5/site-packages/django/template/base.py", line 199, in _render
    return self.nodelist.render(context)
  File "/home/ubunturoot/.pyenv/versions/blog/lib/python3.5/site-packages/django/template/base.py", line 990, in render
    bit = node.render_annotated(context)
  File "/home/ubunturoot/.pyenv/versions/blog/lib/python3.5/site-packages/django/template/base.py", line 957, in render_annotated
    return self.render(context)
  File "/home/ubunturoot/.pyenv/versions/blog/lib/python3.5/site-packages/django/template/loader_tags.py", line 72, in render
    result = block.nodelist.render(context)
  File "/home/ubunturoot/.pyenv/versions/blog/lib/python3.5/site-packages/django/template/base.py", line 990, in render
    bit = node.render_annotated(context)
  File "/home/ubunturoot/.pyenv/versions/blog/lib/python3.5/site-packages/django/template/base.py", line 957, in render_annotated
    return self.render(context)
  File "/home/ubunturoot/.pyenv/versions/blog/lib/python3.5/site-packages/django/template/defaulttags.py", line 216, in render
    nodelist.append(node.render_annotated(context))
  File "/home/ubunturoot/.pyenv/versions/blog/lib/python3.5/site-packages/django/template/base.py", line 957, in render_annotated
    return self.render(context)
  File "/home/ubunturoot/.pyenv/versions/blog/lib/python3.5/site-packages/django/template/defaulttags.py", line 458, in render
    url = reverse(view_name, args=args, kwargs=kwargs, current_app=current_app)
  File "/home/ubunturoot/.pyenv/versions/blog/lib/python3.5/site-packages/django/urls/base.py", line 91, in reverse
    return force_text(iri_to_uri(resolver._reverse_with_prefix(view, prefix, *args, **kwargs)))
  File "/home/ubunturoot/.pyenv/versions/blog/lib/python3.5/site-packages/django/urls/resolvers.py", line 497, in _reverse_with_prefix
    raise NoReverseMatch(msg)
django.urls.exceptions.NoReverseMatch: Reverse for 'article' not found. 'article' is not a valid view function or pattern name.
2017-05-10 13:57:40,110 [Thread-2:-1250952384] [django.request:135] [exception:handle_uncaught_exception] [ERROR]- Internal Server Error: /
Traceback (most recent call last):
  File "/home/ubunturoot/.pyenv/versions/blog/lib/python3.5/site-packages/django/core/handlers/exception.py", line 41, in inner
    response = get_response(request)
  File "/home/ubunturoot/.pyenv/versions/blog/lib/python3.5/site-packages/django/core/handlers/base.py", line 187, in _get_response
    response = self.process_exception_by_middleware(e, request)
  File "/home/ubunturoot/.pyenv/versions/blog/lib/python3.5/site-packages/django/core/handlers/base.py", line 185, in _get_response
    response = wrapped_callback(request, *callback_args, **callback_kwargs)
  File "/home/ubunturoot/blog/blog_project/blog/views.py", line 29, in index
    return render(request, 'index.html', locals())
  File "/home/ubunturoot/.pyenv/versions/blog/lib/python3.5/site-packages/django/shortcuts.py", line 30, in render
    content = loader.render_to_string(template_name, context, request, using=using)
  File "/home/ubunturoot/.pyenv/versions/blog/lib/python3.5/site-packages/django/template/loader.py", line 68, in render_to_string
    return template.render(context, request)
  File "/home/ubunturoot/.pyenv/versions/blog/lib/python3.5/site-packages/django/template/backends/django.py", line 66, in render
    return self.template.render(context)
  File "/home/ubunturoot/.pyenv/versions/blog/lib/python3.5/site-packages/django/template/base.py", line 207, in render
    return self._render(context)
  File "/home/ubunturoot/.pyenv/versions/blog/lib/python3.5/site-packages/django/template/base.py", line 199, in _render
    return self.nodelist.render(context)
  File "/home/ubunturoot/.pyenv/versions/blog/lib/python3.5/site-packages/django/template/base.py", line 990, in render
    bit = node.render_annotated(context)
  File "/home/ubunturoot/.pyenv/versions/blog/lib/python3.5/site-packages/django/template/base.py", line 957, in render_annotated
    return self.render(context)
  File "/home/ubunturoot/.pyenv/versions/blog/lib/python3.5/site-packages/django/template/loader_tags.py", line 177, in render
    return compiled_parent._render(context)
  File "/home/ubunturoot/.pyenv/versions/blog/lib/python3.5/site-packages/django/template/base.py", line 199, in _render
    return self.nodelist.render(context)
  File "/home/ubunturoot/.pyenv/versions/blog/lib/python3.5/site-packages/django/template/base.py", line 990, in render
    bit = node.render_annotated(context)
  File "/home/ubunturoot/.pyenv/versions/blog/lib/python3.5/site-packages/django/template/base.py", line 957, in render_annotated
    return self.render(context)
  File "/home/ubunturoot/.pyenv/versions/blog/lib/python3.5/site-packages/django/template/loader_tags.py", line 72, in render
    result = block.nodelist.render(context)
  File "/home/ubunturoot/.pyenv/versions/blog/lib/python3.5/site-packages/django/template/base.py", line 990, in render
    bit = node.render_annotated(context)
  File "/home/ubunturoot/.pyenv/versions/blog/lib/python3.5/site-packages/django/template/base.py", line 957, in render_annotated
    return self.render(context)
  File "/home/ubunturoot/.pyenv/versions/blog/lib/python3.5/site-packages/django/template/defaulttags.py", line 216, in render
    nodelist.append(node.render_annotated(context))
  File "/home/ubunturoot/.pyenv/versions/blog/lib/python3.5/site-packages/django/template/base.py", line 957, in render_annotated
    return self.render(context)
  File "/home/ubunturoot/.pyenv/versions/blog/lib/python3.5/site-packages/django/template/defaulttags.py", line 458, in render
    url = reverse(view_name, args=args, kwargs=kwargs, current_app=current_app)
  File "/home/ubunturoot/.pyenv/versions/blog/lib/python3.5/site-packages/django/urls/base.py", line 91, in reverse
    return force_text(iri_to_uri(resolver._reverse_with_prefix(view, prefix, *args, **kwargs)))
  File "/home/ubunturoot/.pyenv/versions/blog/lib/python3.5/site-packages/django/urls/resolvers.py", line 497, in _reverse_with_prefix
    raise NoReverseMatch(msg)
django.urls.exceptions.NoReverseMatch: Reverse for 'article' not found. 'article' is not a valid view function or pattern name.
2017-05-10 13:57:44,799 [Thread-3:-1261438144] [django.request:135] [exception:handle_uncaught_exception] [ERROR]- Internal Server Error: /
Traceback (most recent call last):
  File "/home/ubunturoot/.pyenv/versions/blog/lib/python3.5/site-packages/django/core/handlers/exception.py", line 41, in inner
    response = get_response(request)
  File "/home/ubunturoot/.pyenv/versions/blog/lib/python3.5/site-packages/django/core/handlers/base.py", line 187, in _get_response
    response = self.process_exception_by_middleware(e, request)
  File "/home/ubunturoot/.pyenv/versions/blog/lib/python3.5/site-packages/django/core/handlers/base.py", line 185, in _get_response
    response = wrapped_callback(request, *callback_args, **callback_kwargs)
  File "/home/ubunturoot/blog/blog_project/blog/views.py", line 29, in index
    return render(request, 'index.html', locals())
  File "/home/ubunturoot/.pyenv/versions/blog/lib/python3.5/site-packages/django/shortcuts.py", line 30, in render
    content = loader.render_to_string(template_name, context, request, using=using)
  File "/home/ubunturoot/.pyenv/versions/blog/lib/python3.5/site-packages/django/template/loader.py", line 68, in render_to_string
    return template.render(context, request)
  File "/home/ubunturoot/.pyenv/versions/blog/lib/python3.5/site-packages/django/template/backends/django.py", line 66, in render
    return self.template.render(context)
  File "/home/ubunturoot/.pyenv/versions/blog/lib/python3.5/site-packages/django/template/base.py", line 207, in render
    return self._render(context)
  File "/home/ubunturoot/.pyenv/versions/blog/lib/python3.5/site-packages/django/template/base.py", line 199, in _render
    return self.nodelist.render(context)
  File "/home/ubunturoot/.pyenv/versions/blog/lib/python3.5/site-packages/django/template/base.py", line 990, in render
    bit = node.render_annotated(context)
  File "/home/ubunturoot/.pyenv/versions/blog/lib/python3.5/site-packages/django/template/base.py", line 957, in render_annotated
    return self.render(context)
  File "/home/ubunturoot/.pyenv/versions/blog/lib/python3.5/site-packages/django/template/loader_tags.py", line 177, in render
    return compiled_parent._render(context)
  File "/home/ubunturoot/.pyenv/versions/blog/lib/python3.5/site-packages/django/template/base.py", line 199, in _render
    return self.nodelist.render(context)
  File "/home/ubunturoot/.pyenv/versions/blog/lib/python3.5/site-packages/django/template/base.py", line 990, in render
    bit = node.render_annotated(context)
  File "/home/ubunturoot/.pyenv/versions/blog/lib/python3.5/site-packages/django/template/base.py", line 957, in render_annotated
    return self.render(context)
  File "/home/ubunturoot/.pyenv/versions/blog/lib/python3.5/site-packages/django/template/loader_tags.py", line 72, in render
    result = block.nodelist.render(context)
  File "/home/ubunturoot/.pyenv/versions/blog/lib/python3.5/site-packages/django/template/base.py", line 990, in render
    bit = node.render_annotated(context)
  File "/home/ubunturoot/.pyenv/versions/blog/lib/python3.5/site-packages/django/template/base.py", line 957, in render_annotated
    return self.render(context)
  File "/home/ubunturoot/.pyenv/versions/blog/lib/python3.5/site-packages/django/template/defaulttags.py", line 216, in render
    nodelist.append(node.render_annotated(context))
  File "/home/ubunturoot/.pyenv/versions/blog/lib/python3.5/site-packages/django/template/base.py", line 957, in render_annotated
    return self.render(context)
  File "/home/ubunturoot/.pyenv/versions/blog/lib/python3.5/site-packages/django/template/defaulttags.py", line 458, in render
    url = reverse(view_name, args=args, kwargs=kwargs, current_app=current_app)
  File "/home/ubunturoot/.pyenv/versions/blog/lib/python3.5/site-packages/django/urls/base.py", line 91, in reverse
    return force_text(iri_to_uri(resolver._reverse_with_prefix(view, prefix, *args, **kwargs)))
  File "/home/ubunturoot/.pyenv/versions/blog/lib/python3.5/site-packages/django/urls/resolvers.py", line 497, in _reverse_with_prefix
    raise NoReverseMatch(msg)
django.urls.exceptions.NoReverseMatch: Reverse for 'article' not found. 'article' is not a valid view function or pattern name.
2017-05-10 13:57:44,999 [Thread-4:-1271923904] [django.request:135] [exception:handle_uncaught_exception] [ERROR]- Internal Server Error: /
Traceback (most recent call last):
  File "/home/ubunturoot/.pyenv/versions/blog/lib/python3.5/site-packages/django/core/handlers/exception.py", line 41, in inner
    response = get_response(request)
  File "/home/ubunturoot/.pyenv/versions/blog/lib/python3.5/site-packages/django/core/handlers/base.py", line 187, in _get_response
    response = self.process_exception_by_middleware(e, request)
  File "/home/ubunturoot/.pyenv/versions/blog/lib/python3.5/site-packages/django/core/handlers/base.py", line 185, in _get_response
    response = wrapped_callback(request, *callback_args, **callback_kwargs)
  File "/home/ubunturoot/blog/blog_project/blog/views.py", line 29, in index
    return render(request, 'index.html', locals())
  File "/home/ubunturoot/.pyenv/versions/blog/lib/python3.5/site-packages/django/shortcuts.py", line 30, in render
    content = loader.render_to_string(template_name, context, request, using=using)
  File "/home/ubunturoot/.pyenv/versions/blog/lib/python3.5/site-packages/django/template/loader.py", line 68, in render_to_string
    return template.render(context, request)
  File "/home/ubunturoot/.pyenv/versions/blog/lib/python3.5/site-packages/django/template/backends/django.py", line 66, in render
    return self.template.render(context)
  File "/home/ubunturoot/.pyenv/versions/blog/lib/python3.5/site-packages/django/template/base.py", line 207, in render
    return self._render(context)
  File "/home/ubunturoot/.pyenv/versions/blog/lib/python3.5/site-packages/django/template/base.py", line 199, in _render
    return self.nodelist.render(context)
  File "/home/ubunturoot/.pyenv/versions/blog/lib/python3.5/site-packages/django/template/base.py", line 990, in render
    bit = node.render_annotated(context)
  File "/home/ubunturoot/.pyenv/versions/blog/lib/python3.5/site-packages/django/template/base.py", line 957, in render_annotated
    return self.render(context)
  File "/home/ubunturoot/.pyenv/versions/blog/lib/python3.5/site-packages/django/template/loader_tags.py", line 177, in render
    return compiled_parent._render(context)
  File "/home/ubunturoot/.pyenv/versions/blog/lib/python3.5/site-packages/django/template/base.py", line 199, in _render
    return self.nodelist.render(context)
  File "/home/ubunturoot/.pyenv/versions/blog/lib/python3.5/site-packages/django/template/base.py", line 990, in render
    bit = node.render_annotated(context)
  File "/home/ubunturoot/.pyenv/versions/blog/lib/python3.5/site-packages/django/template/base.py", line 957, in render_annotated
    return self.render(context)
  File "/home/ubunturoot/.pyenv/versions/blog/lib/python3.5/site-packages/django/template/loader_tags.py", line 72, in render
    result = block.nodelist.render(context)
  File "/home/ubunturoot/.pyenv/versions/blog/lib/python3.5/site-packages/django/template/base.py", line 990, in render
    bit = node.render_annotated(context)
  File "/home/ubunturoot/.pyenv/versions/blog/lib/python3.5/site-packages/django/template/base.py", line 957, in render_annotated
    return self.render(context)
  File "/home/ubunturoot/.pyenv/versions/blog/lib/python3.5/site-packages/django/template/defaulttags.py", line 216, in render
    nodelist.append(node.render_annotated(context))
  File "/home/ubunturoot/.pyenv/versions/blog/lib/python3.5/site-packages/django/template/base.py", line 957, in render_annotated
    return self.render(context)
  File "/home/ubunturoot/.pyenv/versions/blog/lib/python3.5/site-packages/django/template/defaulttags.py", line 458, in render
    url = reverse(view_name, args=args, kwargs=kwargs, current_app=current_app)
  File "/home/ubunturoot/.pyenv/versions/blog/lib/python3.5/site-packages/django/urls/base.py", line 91, in reverse
    return force_text(iri_to_uri(resolver._reverse_with_prefix(view, prefix, *args, **kwargs)))
  File "/home/ubunturoot/.pyenv/versions/blog/lib/python3.5/site-packages/django/urls/resolvers.py", line 497, in _reverse_with_prefix
    raise NoReverseMatch(msg)
django.urls.exceptions.NoReverseMatch: Reverse for 'article' not found. 'article' is not a valid view function or pattern name.
2017-05-10 14:05:07,430 [Thread-4:-1251214528] [django.request:135] [exception:handle_uncaught_exception] [ERROR]- Internal Server Error: /article
Traceback (most recent call last):
  File "/home/ubunturoot/.pyenv/versions/blog/lib/python3.5/site-packages/django/template/defaulttags.py", line 1038, in find_library
    return parser.libraries[name]
KeyError: 'myfilter'

During handling of the above exception, another exception occurred:

Traceback (most recent call last):
  File "/home/ubunturoot/.pyenv/versions/blog/lib/python3.5/site-packages/django/core/handlers/exception.py", line 41, in inner
    response = get_response(request)
  File "/home/ubunturoot/.pyenv/versions/blog/lib/python3.5/site-packages/django/core/handlers/base.py", line 187, in _get_response
    response = self.process_exception_by_middleware(e, request)
  File "/home/ubunturoot/.pyenv/versions/blog/lib/python3.5/site-packages/django/core/handlers/base.py", line 185, in _get_response
    response = wrapped_callback(request, *callback_args, **callback_kwargs)
  File "/home/ubunturoot/blog/blog_project/blog/views.py", line 37, in article
    return render(request, 'article.html', locals())
  File "/home/ubunturoot/.pyenv/versions/blog/lib/python3.5/site-packages/django/shortcuts.py", line 30, in render
    content = loader.render_to_string(template_name, context, request, using=using)
  File "/home/ubunturoot/.pyenv/versions/blog/lib/python3.5/site-packages/django/template/loader.py", line 67, in render_to_string
    template = get_template(template_name, using=using)
  File "/home/ubunturoot/.pyenv/versions/blog/lib/python3.5/site-packages/django/template/loader.py", line 21, in get_template
    return engine.get_template(template_name)
  File "/home/ubunturoot/.pyenv/versions/blog/lib/python3.5/site-packages/django/template/backends/django.py", line 39, in get_template
    return Template(self.engine.get_template(template_name), self)
  File "/home/ubunturoot/.pyenv/versions/blog/lib/python3.5/site-packages/django/template/engine.py", line 162, in get_template
    template, origin = self.find_template(template_name)
  File "/home/ubunturoot/.pyenv/versions/blog/lib/python3.5/site-packages/django/template/engine.py", line 136, in find_template
    name, template_dirs=dirs, skip=skip,
  File "/home/ubunturoot/.pyenv/versions/blog/lib/python3.5/site-packages/django/template/loaders/base.py", line 44, in get_template
    contents, origin, origin.template_name, self.engine,
  File "/home/ubunturoot/.pyenv/versions/blog/lib/python3.5/site-packages/django/template/base.py", line 191, in __init__
    self.nodelist = self.compile_nodelist()
  File "/home/ubunturoot/.pyenv/versions/blog/lib/python3.5/site-packages/django/template/base.py", line 230, in compile_nodelist
    return parser.parse()
  File "/home/ubunturoot/.pyenv/versions/blog/lib/python3.5/site-packages/django/template/base.py", line 515, in parse
    raise self.error(token, e)
  File "/home/ubunturoot/.pyenv/versions/blog/lib/python3.5/site-packages/django/template/base.py", line 513, in parse
    compiled_result = compile_func(self, token)
  File "/home/ubunturoot/.pyenv/versions/blog/lib/python3.5/site-packages/django/template/loader_tags.py", line 312, in do_extends
    nodelist = parser.parse()
  File "/home/ubunturoot/.pyenv/versions/blog/lib/python3.5/site-packages/django/template/base.py", line 515, in parse
    raise self.error(token, e)
  File "/home/ubunturoot/.pyenv/versions/blog/lib/python3.5/site-packages/django/template/base.py", line 513, in parse
    compiled_result = compile_func(self, token)
  File "/home/ubunturoot/.pyenv/versions/blog/lib/python3.5/site-packages/django/template/defaulttags.py", line 1095, in load
    lib = find_library(parser, name)
  File "/home/ubunturoot/.pyenv/versions/blog/lib/python3.5/site-packages/django/template/defaulttags.py", line 1042, in find_library
    name, "\n".join(sorted(parser.libraries.keys())),
django.template.exceptions.TemplateSyntaxError: 'myfilter' is not a registered tag library. Must be one of:
admin_list
admin_modify
admin_static
admin_urls
cache
i18n
l10n
log
static
staticfiles
tz
2017-05-10 14:28:55,789 [Thread-35:-1271923904] [django.request:135] [exception:handle_uncaught_exception] [ERROR]- Internal Server Error: /article
Traceback (most recent call last):
  File "/home/ubunturoot/.pyenv/versions/blog/lib/python3.5/site-packages/django/template/defaulttags.py", line 1038, in find_library
    return parser.libraries[name]
KeyError: 'myfilter'

During handling of the above exception, another exception occurred:

Traceback (most recent call last):
  File "/home/ubunturoot/.pyenv/versions/blog/lib/python3.5/site-packages/django/core/handlers/exception.py", line 41, in inner
    response = get_response(request)
  File "/home/ubunturoot/.pyenv/versions/blog/lib/python3.5/site-packages/django/core/handlers/base.py", line 187, in _get_response
    response = self.process_exception_by_middleware(e, request)
  File "/home/ubunturoot/.pyenv/versions/blog/lib/python3.5/site-packages/django/core/handlers/base.py", line 185, in _get_response
    response = wrapped_callback(request, *callback_args, **callback_kwargs)
  File "/home/ubunturoot/blog/blog_project/blog/views.py", line 39, in article
    return render(request, 'article.html', locals())
  File "/home/ubunturoot/.pyenv/versions/blog/lib/python3.5/site-packages/django/shortcuts.py", line 30, in render
    content = loader.render_to_string(template_name, context, request, using=using)
  File "/home/ubunturoot/.pyenv/versions/blog/lib/python3.5/site-packages/django/template/loader.py", line 67, in render_to_string
    template = get_template(template_name, using=using)
  File "/home/ubunturoot/.pyenv/versions/blog/lib/python3.5/site-packages/django/template/loader.py", line 21, in get_template
    return engine.get_template(template_name)
  File "/home/ubunturoot/.pyenv/versions/blog/lib/python3.5/site-packages/django/template/backends/django.py", line 39, in get_template
    return Template(self.engine.get_template(template_name), self)
  File "/home/ubunturoot/.pyenv/versions/blog/lib/python3.5/site-packages/django/template/engine.py", line 162, in get_template
    template, origin = self.find_template(template_name)
  File "/home/ubunturoot/.pyenv/versions/blog/lib/python3.5/site-packages/django/template/engine.py", line 136, in find_template
    name, template_dirs=dirs, skip=skip,
  File "/home/ubunturoot/.pyenv/versions/blog/lib/python3.5/site-packages/django/template/loaders/base.py", line 44, in get_template
    contents, origin, origin.template_name, self.engine,
  File "/home/ubunturoot/.pyenv/versions/blog/lib/python3.5/site-packages/django/template/base.py", line 191, in __init__
    self.nodelist = self.compile_nodelist()
  File "/home/ubunturoot/.pyenv/versions/blog/lib/python3.5/site-packages/django/template/base.py", line 230, in compile_nodelist
    return parser.parse()
  File "/home/ubunturoot/.pyenv/versions/blog/lib/python3.5/site-packages/django/template/base.py", line 515, in parse
    raise self.error(token, e)
  File "/home/ubunturoot/.pyenv/versions/blog/lib/python3.5/site-packages/django/template/base.py", line 513, in parse
    compiled_result = compile_func(self, token)
  File "/home/ubunturoot/.pyenv/versions/blog/lib/python3.5/site-packages/django/template/loader_tags.py", line 312, in do_extends
    nodelist = parser.parse()
  File "/home/ubunturoot/.pyenv/versions/blog/lib/python3.5/site-packages/django/template/base.py", line 515, in parse
    raise self.error(token, e)
  File "/home/ubunturoot/.pyenv/versions/blog/lib/python3.5/site-packages/django/template/base.py", line 513, in parse
    compiled_result = compile_func(self, token)
  File "/home/ubunturoot/.pyenv/versions/blog/lib/python3.5/site-packages/django/template/defaulttags.py", line 1095, in load
    lib = find_library(parser, name)
  File "/home/ubunturoot/.pyenv/versions/blog/lib/python3.5/site-packages/django/template/defaulttags.py", line 1042, in find_library
    name, "\n".join(sorted(parser.libraries.keys())),
django.template.exceptions.TemplateSyntaxError: 'myfilter' is not a registered tag library. Must be one of:
admin_list
admin_modify
admin_static
admin_urls
cache
i18n
l10n
log
static
staticfiles
tz
2017-05-10 15:44:01,482 [Thread-2:-1250952384] [django.request:135] [exception:handle_uncaught_exception] [ERROR]- Internal Server Error: /
Traceback (most recent call last):
  File "/home/ubunturoot/.pyenv/versions/blog/lib/python3.5/site-packages/django/core/handlers/exception.py", line 41, in inner
    response = get_response(request)
  File "/home/ubunturoot/.pyenv/versions/blog/lib/python3.5/site-packages/django/core/handlers/base.py", line 187, in _get_response
    response = self.process_exception_by_middleware(e, request)
  File "/home/ubunturoot/.pyenv/versions/blog/lib/python3.5/site-packages/django/core/handlers/base.py", line 185, in _get_response
    response = wrapped_callback(request, *callback_args, **callback_kwargs)
  File "/home/ubunturoot/blog/blog_project/blog/views.py", line 31, in index
    return render(request, 'index.html', locals())
  File "/home/ubunturoot/.pyenv/versions/blog/lib/python3.5/site-packages/django/shortcuts.py", line 30, in render
    content = loader.render_to_string(template_name, context, request, using=using)
  File "/home/ubunturoot/.pyenv/versions/blog/lib/python3.5/site-packages/django/template/loader.py", line 68, in render_to_string
    return template.render(context, request)
  File "/home/ubunturoot/.pyenv/versions/blog/lib/python3.5/site-packages/django/template/backends/django.py", line 66, in render
    return self.template.render(context)
  File "/home/ubunturoot/.pyenv/versions/blog/lib/python3.5/site-packages/django/template/base.py", line 207, in render
    return self._render(context)
  File "/home/ubunturoot/.pyenv/versions/blog/lib/python3.5/site-packages/django/template/base.py", line 199, in _render
    return self.nodelist.render(context)
  File "/home/ubunturoot/.pyenv/versions/blog/lib/python3.5/site-packages/django/template/base.py", line 990, in render
    bit = node.render_annotated(context)
  File "/home/ubunturoot/.pyenv/versions/blog/lib/python3.5/site-packages/django/template/base.py", line 957, in render_annotated
    return self.render(context)
  File "/home/ubunturoot/.pyenv/versions/blog/lib/python3.5/site-packages/django/template/loader_tags.py", line 177, in render
    return compiled_parent._render(context)
  File "/home/ubunturoot/.pyenv/versions/blog/lib/python3.5/site-packages/django/template/base.py", line 199, in _render
    return self.nodelist.render(context)
  File "/home/ubunturoot/.pyenv/versions/blog/lib/python3.5/site-packages/django/template/base.py", line 990, in render
    bit = node.render_annotated(context)
  File "/home/ubunturoot/.pyenv/versions/blog/lib/python3.5/site-packages/django/template/base.py", line 957, in render_annotated
    return self.render(context)
  File "/home/ubunturoot/.pyenv/versions/blog/lib/python3.5/site-packages/django/template/defaulttags.py", line 216, in render
    nodelist.append(node.render_annotated(context))
  File "/home/ubunturoot/.pyenv/versions/blog/lib/python3.5/site-packages/django/template/base.py", line 957, in render_annotated
    return self.render(context)
  File "/home/ubunturoot/.pyenv/versions/blog/lib/python3.5/site-packages/django/template/defaulttags.py", line 458, in render
    url = reverse(view_name, args=args, kwargs=kwargs, current_app=current_app)
  File "/home/ubunturoot/.pyenv/versions/blog/lib/python3.5/site-packages/django/urls/base.py", line 91, in reverse
    return force_text(iri_to_uri(resolver._reverse_with_prefix(view, prefix, *args, **kwargs)))
  File "/home/ubunturoot/.pyenv/versions/blog/lib/python3.5/site-packages/django/urls/resolvers.py", line 497, in _reverse_with_prefix
    raise NoReverseMatch(msg)
django.urls.exceptions.NoReverseMatch: Reverse for 'category' with no arguments not found. 1 pattern(s) tried: ['$category$']
2017-05-10 15:47:06,841 [Thread-2:-1251476672] [django.request:152] [base:get_response] [WARNING]- Not Found: /
2017-05-10 15:47:47,445 [Thread-2:-1250428096] [django.request:135] [exception:handle_uncaught_exception] [ERROR]- Internal Server Error: /
Traceback (most recent call last):
  File "/home/ubunturoot/.pyenv/versions/blog/lib/python3.5/site-packages/django/core/handlers/exception.py", line 41, in inner
    response = get_response(request)
  File "/home/ubunturoot/.pyenv/versions/blog/lib/python3.5/site-packages/django/core/handlers/base.py", line 187, in _get_response
    response = self.process_exception_by_middleware(e, request)
  File "/home/ubunturoot/.pyenv/versions/blog/lib/python3.5/site-packages/django/core/handlers/base.py", line 185, in _get_response
    response = wrapped_callback(request, *callback_args, **callback_kwargs)
  File "/home/ubunturoot/blog/blog_project/blog/views.py", line 31, in index
    return render(request, 'index.html', locals())
  File "/home/ubunturoot/.pyenv/versions/blog/lib/python3.5/site-packages/django/shortcuts.py", line 30, in render
    content = loader.render_to_string(template_name, context, request, using=using)
  File "/home/ubunturoot/.pyenv/versions/blog/lib/python3.5/site-packages/django/template/loader.py", line 68, in render_to_string
    return template.render(context, request)
  File "/home/ubunturoot/.pyenv/versions/blog/lib/python3.5/site-packages/django/template/backends/django.py", line 66, in render
    return self.template.render(context)
  File "/home/ubunturoot/.pyenv/versions/blog/lib/python3.5/site-packages/django/template/base.py", line 207, in render
    return self._render(context)
  File "/home/ubunturoot/.pyenv/versions/blog/lib/python3.5/site-packages/django/template/base.py", line 199, in _render
    return self.nodelist.render(context)
  File "/home/ubunturoot/.pyenv/versions/blog/lib/python3.5/site-packages/django/template/base.py", line 990, in render
    bit = node.render_annotated(context)
  File "/home/ubunturoot/.pyenv/versions/blog/lib/python3.5/site-packages/django/template/base.py", line 957, in render_annotated
    return self.render(context)
  File "/home/ubunturoot/.pyenv/versions/blog/lib/python3.5/site-packages/django/template/loader_tags.py", line 177, in render
    return compiled_parent._render(context)
  File "/home/ubunturoot/.pyenv/versions/blog/lib/python3.5/site-packages/django/template/base.py", line 199, in _render
    return self.nodelist.render(context)
  File "/home/ubunturoot/.pyenv/versions/blog/lib/python3.5/site-packages/django/template/base.py", line 990, in render
    bit = node.render_annotated(context)
  File "/home/ubunturoot/.pyenv/versions/blog/lib/python3.5/site-packages/django/template/base.py", line 957, in render_annotated
    return self.render(context)
  File "/home/ubunturoot/.pyenv/versions/blog/lib/python3.5/site-packages/django/template/defaulttags.py", line 216, in render
    nodelist.append(node.render_annotated(context))
  File "/home/ubunturoot/.pyenv/versions/blog/lib/python3.5/site-packages/django/template/base.py", line 957, in render_annotated
    return self.render(context)
  File "/home/ubunturoot/.pyenv/versions/blog/lib/python3.5/site-packages/django/template/defaulttags.py", line 458, in render
    url = reverse(view_name, args=args, kwargs=kwargs, current_app=current_app)
  File "/home/ubunturoot/.pyenv/versions/blog/lib/python3.5/site-packages/django/urls/base.py", line 91, in reverse
    return force_text(iri_to_uri(resolver._reverse_with_prefix(view, prefix, *args, **kwargs)))
  File "/home/ubunturoot/.pyenv/versions/blog/lib/python3.5/site-packages/django/urls/resolvers.py", line 497, in _reverse_with_prefix
    raise NoReverseMatch(msg)
django.urls.exceptions.NoReverseMatch: Reverse for 'category' with no arguments not found. 1 pattern(s) tried: ['$category$']
2017-05-10 15:48:12,160 [Thread-7:-1287660736] [django.request:135] [exception:handle_uncaught_exception] [ERROR]- Internal Server Error: /
Traceback (most recent call last):
  File "/home/ubunturoot/.pyenv/versions/blog/lib/python3.5/site-packages/django/core/handlers/exception.py", line 41, in inner
    response = get_response(request)
  File "/home/ubunturoot/.pyenv/versions/blog/lib/python3.5/site-packages/django/core/handlers/base.py", line 187, in _get_response
    response = self.process_exception_by_middleware(e, request)
  File "/home/ubunturoot/.pyenv/versions/blog/lib/python3.5/site-packages/django/core/handlers/base.py", line 185, in _get_response
    response = wrapped_callback(request, *callback_args, **callback_kwargs)
  File "/home/ubunturoot/blog/blog_project/blog/views.py", line 31, in index
    return render(request, 'index.html', locals())
  File "/home/ubunturoot/.pyenv/versions/blog/lib/python3.5/site-packages/django/shortcuts.py", line 30, in render
    content = loader.render_to_string(template_name, context, request, using=using)
  File "/home/ubunturoot/.pyenv/versions/blog/lib/python3.5/site-packages/django/template/loader.py", line 68, in render_to_string
    return template.render(context, request)
  File "/home/ubunturoot/.pyenv/versions/blog/lib/python3.5/site-packages/django/template/backends/django.py", line 66, in render
    return self.template.render(context)
  File "/home/ubunturoot/.pyenv/versions/blog/lib/python3.5/site-packages/django/template/base.py", line 207, in render
    return self._render(context)
  File "/home/ubunturoot/.pyenv/versions/blog/lib/python3.5/site-packages/django/template/base.py", line 199, in _render
    return self.nodelist.render(context)
  File "/home/ubunturoot/.pyenv/versions/blog/lib/python3.5/site-packages/django/template/base.py", line 990, in render
    bit = node.render_annotated(context)
  File "/home/ubunturoot/.pyenv/versions/blog/lib/python3.5/site-packages/django/template/base.py", line 957, in render_annotated
    return self.render(context)
  File "/home/ubunturoot/.pyenv/versions/blog/lib/python3.5/site-packages/django/template/loader_tags.py", line 177, in render
    return compiled_parent._render(context)
  File "/home/ubunturoot/.pyenv/versions/blog/lib/python3.5/site-packages/django/template/base.py", line 199, in _render
    return self.nodelist.render(context)
  File "/home/ubunturoot/.pyenv/versions/blog/lib/python3.5/site-packages/django/template/base.py", line 990, in render
    bit = node.render_annotated(context)
  File "/home/ubunturoot/.pyenv/versions/blog/lib/python3.5/site-packages/django/template/base.py", line 957, in render_annotated
    return self.render(context)
  File "/home/ubunturoot/.pyenv/versions/blog/lib/python3.5/site-packages/django/template/defaulttags.py", line 216, in render
    nodelist.append(node.render_annotated(context))
  File "/home/ubunturoot/.pyenv/versions/blog/lib/python3.5/site-packages/django/template/base.py", line 957, in render_annotated
    return self.render(context)
  File "/home/ubunturoot/.pyenv/versions/blog/lib/python3.5/site-packages/django/template/defaulttags.py", line 458, in render
    url = reverse(view_name, args=args, kwargs=kwargs, current_app=current_app)
  File "/home/ubunturoot/.pyenv/versions/blog/lib/python3.5/site-packages/django/urls/base.py", line 91, in reverse
    return force_text(iri_to_uri(resolver._reverse_with_prefix(view, prefix, *args, **kwargs)))
  File "/home/ubunturoot/.pyenv/versions/blog/lib/python3.5/site-packages/django/urls/resolvers.py", line 497, in _reverse_with_prefix
    raise NoReverseMatch(msg)
django.urls.exceptions.NoReverseMatch: Reverse for 'category' with no arguments not found. 1 pattern(s) tried: ['$category$']
2017-05-10 15:49:12,482 [Thread-2:-1251214528] [django.request:135] [exception:handle_uncaught_exception] [ERROR]- Internal Server Error: /
Traceback (most recent call last):
  File "/home/ubunturoot/.pyenv/versions/blog/lib/python3.5/site-packages/django/core/handlers/exception.py", line 41, in inner
    response = get_response(request)
  File "/home/ubunturoot/.pyenv/versions/blog/lib/python3.5/site-packages/django/core/handlers/base.py", line 187, in _get_response
    response = self.process_exception_by_middleware(e, request)
  File "/home/ubunturoot/.pyenv/versions/blog/lib/python3.5/site-packages/django/core/handlers/base.py", line 185, in _get_response
    response = wrapped_callback(request, *callback_args, **callback_kwargs)
  File "/home/ubunturoot/blog/blog_project/blog/views.py", line 31, in index
    return render(request, 'index.html', locals())
  File "/home/ubunturoot/.pyenv/versions/blog/lib/python3.5/site-packages/django/shortcuts.py", line 30, in render
    content = loader.render_to_string(template_name, context, request, using=using)
  File "/home/ubunturoot/.pyenv/versions/blog/lib/python3.5/site-packages/django/template/loader.py", line 68, in render_to_string
    return template.render(context, request)
  File "/home/ubunturoot/.pyenv/versions/blog/lib/python3.5/site-packages/django/template/backends/django.py", line 66, in render
    return self.template.render(context)
  File "/home/ubunturoot/.pyenv/versions/blog/lib/python3.5/site-packages/django/template/base.py", line 207, in render
    return self._render(context)
  File "/home/ubunturoot/.pyenv/versions/blog/lib/python3.5/site-packages/django/template/base.py", line 199, in _render
    return self.nodelist.render(context)
  File "/home/ubunturoot/.pyenv/versions/blog/lib/python3.5/site-packages/django/template/base.py", line 990, in render
    bit = node.render_annotated(context)
  File "/home/ubunturoot/.pyenv/versions/blog/lib/python3.5/site-packages/django/template/base.py", line 957, in render_annotated
    return self.render(context)
  File "/home/ubunturoot/.pyenv/versions/blog/lib/python3.5/site-packages/django/template/loader_tags.py", line 177, in render
    return compiled_parent._render(context)
  File "/home/ubunturoot/.pyenv/versions/blog/lib/python3.5/site-packages/django/template/base.py", line 199, in _render
    return self.nodelist.render(context)
  File "/home/ubunturoot/.pyenv/versions/blog/lib/python3.5/site-packages/django/template/base.py", line 990, in render
    bit = node.render_annotated(context)
  File "/home/ubunturoot/.pyenv/versions/blog/lib/python3.5/site-packages/django/template/base.py", line 957, in render_annotated
    return self.render(context)
  File "/home/ubunturoot/.pyenv/versions/blog/lib/python3.5/site-packages/django/template/defaulttags.py", line 216, in render
    nodelist.append(node.render_annotated(context))
  File "/home/ubunturoot/.pyenv/versions/blog/lib/python3.5/site-packages/django/template/base.py", line 957, in render_annotated
    return self.render(context)
  File "/home/ubunturoot/.pyenv/versions/blog/lib/python3.5/site-packages/django/template/defaulttags.py", line 458, in render
    url = reverse(view_name, args=args, kwargs=kwargs, current_app=current_app)
  File "/home/ubunturoot/.pyenv/versions/blog/lib/python3.5/site-packages/django/urls/base.py", line 91, in reverse
    return force_text(iri_to_uri(resolver._reverse_with_prefix(view, prefix, *args, **kwargs)))
  File "/home/ubunturoot/.pyenv/versions/blog/lib/python3.5/site-packages/django/urls/resolvers.py", line 497, in _reverse_with_prefix
    raise NoReverseMatch(msg)
django.urls.exceptions.NoReverseMatch: Reverse for 'category' with no arguments not found. 1 pattern(s) tried: ['$category$']
2017-05-10 15:49:22,501 [Thread-2:-1250952384] [django.request:135] [exception:handle_uncaught_exception] [ERROR]- Internal Server Error: /
Traceback (most recent call last):
  File "/home/ubunturoot/.pyenv/versions/blog/lib/python3.5/site-packages/django/core/handlers/exception.py", line 41, in inner
    response = get_response(request)
  File "/home/ubunturoot/.pyenv/versions/blog/lib/python3.5/site-packages/django/core/handlers/base.py", line 187, in _get_response
    response = self.process_exception_by_middleware(e, request)
  File "/home/ubunturoot/.pyenv/versions/blog/lib/python3.5/site-packages/django/core/handlers/base.py", line 185, in _get_response
    response = wrapped_callback(request, *callback_args, **callback_kwargs)
  File "/home/ubunturoot/blog/blog_project/blog/views.py", line 31, in index
    return render(request, 'index.html', locals())
  File "/home/ubunturoot/.pyenv/versions/blog/lib/python3.5/site-packages/django/shortcuts.py", line 30, in render
    content = loader.render_to_string(template_name, context, request, using=using)
  File "/home/ubunturoot/.pyenv/versions/blog/lib/python3.5/site-packages/django/template/loader.py", line 68, in render_to_string
    return template.render(context, request)
  File "/home/ubunturoot/.pyenv/versions/blog/lib/python3.5/site-packages/django/template/backends/django.py", line 66, in render
    return self.template.render(context)
  File "/home/ubunturoot/.pyenv/versions/blog/lib/python3.5/site-packages/django/template/base.py", line 207, in render
    return self._render(context)
  File "/home/ubunturoot/.pyenv/versions/blog/lib/python3.5/site-packages/django/template/base.py", line 199, in _render
    return self.nodelist.render(context)
  File "/home/ubunturoot/.pyenv/versions/blog/lib/python3.5/site-packages/django/template/base.py", line 990, in render
    bit = node.render_annotated(context)
  File "/home/ubunturoot/.pyenv/versions/blog/lib/python3.5/site-packages/django/template/base.py", line 957, in render_annotated
    return self.render(context)
  File "/home/ubunturoot/.pyenv/versions/blog/lib/python3.5/site-packages/django/template/loader_tags.py", line 177, in render
    return compiled_parent._render(context)
  File "/home/ubunturoot/.pyenv/versions/blog/lib/python3.5/site-packages/django/template/base.py", line 199, in _render
    return self.nodelist.render(context)
  File "/home/ubunturoot/.pyenv/versions/blog/lib/python3.5/site-packages/django/template/base.py", line 990, in render
    bit = node.render_annotated(context)
  File "/home/ubunturoot/.pyenv/versions/blog/lib/python3.5/site-packages/django/template/base.py", line 957, in render_annotated
    return self.render(context)
  File "/home/ubunturoot/.pyenv/versions/blog/lib/python3.5/site-packages/django/template/defaulttags.py", line 216, in render
    nodelist.append(node.render_annotated(context))
  File "/home/ubunturoot/.pyenv/versions/blog/lib/python3.5/site-packages/django/template/base.py", line 957, in render_annotated
    return self.render(context)
  File "/home/ubunturoot/.pyenv/versions/blog/lib/python3.5/site-packages/django/template/defaulttags.py", line 458, in render
    url = reverse(view_name, args=args, kwargs=kwargs, current_app=current_app)
  File "/home/ubunturoot/.pyenv/versions/blog/lib/python3.5/site-packages/django/urls/base.py", line 91, in reverse
    return force_text(iri_to_uri(resolver._reverse_with_prefix(view, prefix, *args, **kwargs)))
  File "/home/ubunturoot/.pyenv/versions/blog/lib/python3.5/site-packages/django/urls/resolvers.py", line 497, in _reverse_with_prefix
    raise NoReverseMatch(msg)
django.urls.exceptions.NoReverseMatch: Reverse for 'category' with no arguments not found. 1 pattern(s) tried: ['$category$']
2017-05-10 15:50:20,739 [Thread-2:-1250952384] [django.request:152] [base:get_response] [WARNING]- Not Found: /
2017-05-10 15:50:41,973 [Thread-2:-1251476672] [django.request:152] [base:get_response] [WARNING]- Not Found: /
2017-05-10 15:50:47,271 [Thread-3:-1251476672] [django.request:152] [base:get_response] [WARNING]- Not Found: /
2017-05-10 15:51:05,064 [Thread-2:-1251214528] [django.request:135] [exception:handle_uncaught_exception] [ERROR]- Internal Server Error: /
Traceback (most recent call last):
  File "/home/ubunturoot/.pyenv/versions/blog/lib/python3.5/site-packages/django/core/handlers/exception.py", line 41, in inner
    response = get_response(request)
  File "/home/ubunturoot/.pyenv/versions/blog/lib/python3.5/site-packages/django/core/handlers/base.py", line 187, in _get_response
    response = self.process_exception_by_middleware(e, request)
  File "/home/ubunturoot/.pyenv/versions/blog/lib/python3.5/site-packages/django/core/handlers/base.py", line 185, in _get_response
    response = wrapped_callback(request, *callback_args, **callback_kwargs)
  File "/home/ubunturoot/blog/blog_project/blog/views.py", line 31, in index
    return render(request, 'index.html', locals())
  File "/home/ubunturoot/.pyenv/versions/blog/lib/python3.5/site-packages/django/shortcuts.py", line 30, in render
    content = loader.render_to_string(template_name, context, request, using=using)
  File "/home/ubunturoot/.pyenv/versions/blog/lib/python3.5/site-packages/django/template/loader.py", line 68, in render_to_string
    return template.render(context, request)
  File "/home/ubunturoot/.pyenv/versions/blog/lib/python3.5/site-packages/django/template/backends/django.py", line 66, in render
    return self.template.render(context)
  File "/home/ubunturoot/.pyenv/versions/blog/lib/python3.5/site-packages/django/template/base.py", line 207, in render
    return self._render(context)
  File "/home/ubunturoot/.pyenv/versions/blog/lib/python3.5/site-packages/django/template/base.py", line 199, in _render
    return self.nodelist.render(context)
  File "/home/ubunturoot/.pyenv/versions/blog/lib/python3.5/site-packages/django/template/base.py", line 990, in render
    bit = node.render_annotated(context)
  File "/home/ubunturoot/.pyenv/versions/blog/lib/python3.5/site-packages/django/template/base.py", line 957, in render_annotated
    return self.render(context)
  File "/home/ubunturoot/.pyenv/versions/blog/lib/python3.5/site-packages/django/template/loader_tags.py", line 177, in render
    return compiled_parent._render(context)
  File "/home/ubunturoot/.pyenv/versions/blog/lib/python3.5/site-packages/django/template/base.py", line 199, in _render
    return self.nodelist.render(context)
  File "/home/ubunturoot/.pyenv/versions/blog/lib/python3.5/site-packages/django/template/base.py", line 990, in render
    bit = node.render_annotated(context)
  File "/home/ubunturoot/.pyenv/versions/blog/lib/python3.5/site-packages/django/template/base.py", line 957, in render_annotated
    return self.render(context)
  File "/home/ubunturoot/.pyenv/versions/blog/lib/python3.5/site-packages/django/template/defaulttags.py", line 216, in render
    nodelist.append(node.render_annotated(context))
  File "/home/ubunturoot/.pyenv/versions/blog/lib/python3.5/site-packages/django/template/base.py", line 957, in render_annotated
    return self.render(context)
  File "/home/ubunturoot/.pyenv/versions/blog/lib/python3.5/site-packages/django/template/defaulttags.py", line 458, in render
    url = reverse(view_name, args=args, kwargs=kwargs, current_app=current_app)
  File "/home/ubunturoot/.pyenv/versions/blog/lib/python3.5/site-packages/django/urls/base.py", line 91, in reverse
    return force_text(iri_to_uri(resolver._reverse_with_prefix(view, prefix, *args, **kwargs)))
  File "/home/ubunturoot/.pyenv/versions/blog/lib/python3.5/site-packages/django/urls/resolvers.py", line 497, in _reverse_with_prefix
    raise NoReverseMatch(msg)
django.urls.exceptions.NoReverseMatch: Reverse for 'category' with no arguments not found. 1 pattern(s) tried: ['$category$']
2017-05-10 15:53:14,579 [Thread-2:-1250952384] [django.request:135] [exception:handle_uncaught_exception] [ERROR]- Internal Server Error: /
Traceback (most recent call last):
  File "/home/ubunturoot/.pyenv/versions/blog/lib/python3.5/site-packages/django/core/handlers/exception.py", line 41, in inner
    response = get_response(request)
  File "/home/ubunturoot/.pyenv/versions/blog/lib/python3.5/site-packages/django/core/handlers/base.py", line 187, in _get_response
    response = self.process_exception_by_middleware(e, request)
  File "/home/ubunturoot/.pyenv/versions/blog/lib/python3.5/site-packages/django/core/handlers/base.py", line 185, in _get_response
    response = wrapped_callback(request, *callback_args, **callback_kwargs)
  File "/home/ubunturoot/blog/blog_project/blog/views.py", line 31, in index
    return render(request, 'index.html', locals())
  File "/home/ubunturoot/.pyenv/versions/blog/lib/python3.5/site-packages/django/shortcuts.py", line 30, in render
    content = loader.render_to_string(template_name, context, request, using=using)
  File "/home/ubunturoot/.pyenv/versions/blog/lib/python3.5/site-packages/django/template/loader.py", line 68, in render_to_string
    return template.render(context, request)
  File "/home/ubunturoot/.pyenv/versions/blog/lib/python3.5/site-packages/django/template/backends/django.py", line 66, in render
    return self.template.render(context)
  File "/home/ubunturoot/.pyenv/versions/blog/lib/python3.5/site-packages/django/template/base.py", line 207, in render
    return self._render(context)
  File "/home/ubunturoot/.pyenv/versions/blog/lib/python3.5/site-packages/django/template/base.py", line 199, in _render
    return self.nodelist.render(context)
  File "/home/ubunturoot/.pyenv/versions/blog/lib/python3.5/site-packages/django/template/base.py", line 990, in render
    bit = node.render_annotated(context)
  File "/home/ubunturoot/.pyenv/versions/blog/lib/python3.5/site-packages/django/template/base.py", line 957, in render_annotated
    return self.render(context)
  File "/home/ubunturoot/.pyenv/versions/blog/lib/python3.5/site-packages/django/template/loader_tags.py", line 177, in render
    return compiled_parent._render(context)
  File "/home/ubunturoot/.pyenv/versions/blog/lib/python3.5/site-packages/django/template/base.py", line 199, in _render
    return self.nodelist.render(context)
  File "/home/ubunturoot/.pyenv/versions/blog/lib/python3.5/site-packages/django/template/base.py", line 990, in render
    bit = node.render_annotated(context)
  File "/home/ubunturoot/.pyenv/versions/blog/lib/python3.5/site-packages/django/template/base.py", line 957, in render_annotated
    return self.render(context)
  File "/home/ubunturoot/.pyenv/versions/blog/lib/python3.5/site-packages/django/template/defaulttags.py", line 216, in render
    nodelist.append(node.render_annotated(context))
  File "/home/ubunturoot/.pyenv/versions/blog/lib/python3.5/site-packages/django/template/base.py", line 957, in render_annotated
    return self.render(context)
  File "/home/ubunturoot/.pyenv/versions/blog/lib/python3.5/site-packages/django/template/defaulttags.py", line 458, in render
    url = reverse(view_name, args=args, kwargs=kwargs, current_app=current_app)
  File "/home/ubunturoot/.pyenv/versions/blog/lib/python3.5/site-packages/django/urls/base.py", line 91, in reverse
    return force_text(iri_to_uri(resolver._reverse_with_prefix(view, prefix, *args, **kwargs)))
  File "/home/ubunturoot/.pyenv/versions/blog/lib/python3.5/site-packages/django/urls/resolvers.py", line 497, in _reverse_with_prefix
    raise NoReverseMatch(msg)
django.urls.exceptions.NoReverseMatch: Reverse for 'category' with no arguments not found. 1 pattern(s) tried: ['$category/$']
2017-05-10 15:53:16,417 [Thread-3:-1250952384] [django.request:135] [exception:handle_uncaught_exception] [ERROR]- Internal Server Error: /
Traceback (most recent call last):
  File "/home/ubunturoot/.pyenv/versions/blog/lib/python3.5/site-packages/django/core/handlers/exception.py", line 41, in inner
    response = get_response(request)
  File "/home/ubunturoot/.pyenv/versions/blog/lib/python3.5/site-packages/django/core/handlers/base.py", line 187, in _get_response
    response = self.process_exception_by_middleware(e, request)
  File "/home/ubunturoot/.pyenv/versions/blog/lib/python3.5/site-packages/django/core/handlers/base.py", line 185, in _get_response
    response = wrapped_callback(request, *callback_args, **callback_kwargs)
  File "/home/ubunturoot/blog/blog_project/blog/views.py", line 31, in index
    return render(request, 'index.html', locals())
  File "/home/ubunturoot/.pyenv/versions/blog/lib/python3.5/site-packages/django/shortcuts.py", line 30, in render
    content = loader.render_to_string(template_name, context, request, using=using)
  File "/home/ubunturoot/.pyenv/versions/blog/lib/python3.5/site-packages/django/template/loader.py", line 68, in render_to_string
    return template.render(context, request)
  File "/home/ubunturoot/.pyenv/versions/blog/lib/python3.5/site-packages/django/template/backends/django.py", line 66, in render
    return self.template.render(context)
  File "/home/ubunturoot/.pyenv/versions/blog/lib/python3.5/site-packages/django/template/base.py", line 207, in render
    return self._render(context)
  File "/home/ubunturoot/.pyenv/versions/blog/lib/python3.5/site-packages/django/template/base.py", line 199, in _render
    return self.nodelist.render(context)
  File "/home/ubunturoot/.pyenv/versions/blog/lib/python3.5/site-packages/django/template/base.py", line 990, in render
    bit = node.render_annotated(context)
  File "/home/ubunturoot/.pyenv/versions/blog/lib/python3.5/site-packages/django/template/base.py", line 957, in render_annotated
    return self.render(context)
  File "/home/ubunturoot/.pyenv/versions/blog/lib/python3.5/site-packages/django/template/loader_tags.py", line 177, in render
    return compiled_parent._render(context)
  File "/home/ubunturoot/.pyenv/versions/blog/lib/python3.5/site-packages/django/template/base.py", line 199, in _render
    return self.nodelist.render(context)
  File "/home/ubunturoot/.pyenv/versions/blog/lib/python3.5/site-packages/django/template/base.py", line 990, in render
    bit = node.render_annotated(context)
  File "/home/ubunturoot/.pyenv/versions/blog/lib/python3.5/site-packages/django/template/base.py", line 957, in render_annotated
    return self.render(context)
  File "/home/ubunturoot/.pyenv/versions/blog/lib/python3.5/site-packages/django/template/defaulttags.py", line 216, in render
    nodelist.append(node.render_annotated(context))
  File "/home/ubunturoot/.pyenv/versions/blog/lib/python3.5/site-packages/django/template/base.py", line 957, in render_annotated
    return self.render(context)
  File "/home/ubunturoot/.pyenv/versions/blog/lib/python3.5/site-packages/django/template/defaulttags.py", line 458, in render
    url = reverse(view_name, args=args, kwargs=kwargs, current_app=current_app)
  File "/home/ubunturoot/.pyenv/versions/blog/lib/python3.5/site-packages/django/urls/base.py", line 91, in reverse
    return force_text(iri_to_uri(resolver._reverse_with_prefix(view, prefix, *args, **kwargs)))
  File "/home/ubunturoot/.pyenv/versions/blog/lib/python3.5/site-packages/django/urls/resolvers.py", line 497, in _reverse_with_prefix
    raise NoReverseMatch(msg)
django.urls.exceptions.NoReverseMatch: Reverse for 'category' with no arguments not found. 1 pattern(s) tried: ['$category/$']
2017-05-10 15:53:16,689 [Thread-4:-1263535296] [django.request:135] [exception:handle_uncaught_exception] [ERROR]- Internal Server Error: /
Traceback (most recent call last):
  File "/home/ubunturoot/.pyenv/versions/blog/lib/python3.5/site-packages/django/core/handlers/exception.py", line 41, in inner
    response = get_response(request)
  File "/home/ubunturoot/.pyenv/versions/blog/lib/python3.5/site-packages/django/core/handlers/base.py", line 187, in _get_response
    response = self.process_exception_by_middleware(e, request)
  File "/home/ubunturoot/.pyenv/versions/blog/lib/python3.5/site-packages/django/core/handlers/base.py", line 185, in _get_response
    response = wrapped_callback(request, *callback_args, **callback_kwargs)
  File "/home/ubunturoot/blog/blog_project/blog/views.py", line 31, in index
    return render(request, 'index.html', locals())
  File "/home/ubunturoot/.pyenv/versions/blog/lib/python3.5/site-packages/django/shortcuts.py", line 30, in render
    content = loader.render_to_string(template_name, context, request, using=using)
  File "/home/ubunturoot/.pyenv/versions/blog/lib/python3.5/site-packages/django/template/loader.py", line 68, in render_to_string
    return template.render(context, request)
  File "/home/ubunturoot/.pyenv/versions/blog/lib/python3.5/site-packages/django/template/backends/django.py", line 66, in render
    return self.template.render(context)
  File "/home/ubunturoot/.pyenv/versions/blog/lib/python3.5/site-packages/django/template/base.py", line 207, in render
    return self._render(context)
  File "/home/ubunturoot/.pyenv/versions/blog/lib/python3.5/site-packages/django/template/base.py", line 199, in _render
    return self.nodelist.render(context)
  File "/home/ubunturoot/.pyenv/versions/blog/lib/python3.5/site-packages/django/template/base.py", line 990, in render
    bit = node.render_annotated(context)
  File "/home/ubunturoot/.pyenv/versions/blog/lib/python3.5/site-packages/django/template/base.py", line 957, in render_annotated
    return self.render(context)
  File "/home/ubunturoot/.pyenv/versions/blog/lib/python3.5/site-packages/django/template/loader_tags.py", line 177, in render
    return compiled_parent._render(context)
  File "/home/ubunturoot/.pyenv/versions/blog/lib/python3.5/site-packages/django/template/base.py", line 199, in _render
    return self.nodelist.render(context)
  File "/home/ubunturoot/.pyenv/versions/blog/lib/python3.5/site-packages/django/template/base.py", line 990, in render
    bit = node.render_annotated(context)
  File "/home/ubunturoot/.pyenv/versions/blog/lib/python3.5/site-packages/django/template/base.py", line 957, in render_annotated
    return self.render(context)
  File "/home/ubunturoot/.pyenv/versions/blog/lib/python3.5/site-packages/django/template/defaulttags.py", line 216, in render
    nodelist.append(node.render_annotated(context))
  File "/home/ubunturoot/.pyenv/versions/blog/lib/python3.5/site-packages/django/template/base.py", line 957, in render_annotated
    return self.render(context)
  File "/home/ubunturoot/.pyenv/versions/blog/lib/python3.5/site-packages/django/template/defaulttags.py", line 458, in render
    url = reverse(view_name, args=args, kwargs=kwargs, current_app=current_app)
  File "/home/ubunturoot/.pyenv/versions/blog/lib/python3.5/site-packages/django/urls/base.py", line 91, in reverse
    return force_text(iri_to_uri(resolver._reverse_with_prefix(view, prefix, *args, **kwargs)))
  File "/home/ubunturoot/.pyenv/versions/blog/lib/python3.5/site-packages/django/urls/resolvers.py", line 497, in _reverse_with_prefix
    raise NoReverseMatch(msg)
django.urls.exceptions.NoReverseMatch: Reverse for 'category' with no arguments not found. 1 pattern(s) tried: ['$category/$']
2017-05-10 15:53:16,929 [Thread-5:-1250952384] [django.request:135] [exception:handle_uncaught_exception] [ERROR]- Internal Server Error: /
Traceback (most recent call last):
  File "/home/ubunturoot/.pyenv/versions/blog/lib/python3.5/site-packages/django/core/handlers/exception.py", line 41, in inner
    response = get_response(request)
  File "/home/ubunturoot/.pyenv/versions/blog/lib/python3.5/site-packages/django/core/handlers/base.py", line 187, in _get_response
    response = self.process_exception_by_middleware(e, request)
  File "/home/ubunturoot/.pyenv/versions/blog/lib/python3.5/site-packages/django/core/handlers/base.py", line 185, in _get_response
    response = wrapped_callback(request, *callback_args, **callback_kwargs)
  File "/home/ubunturoot/blog/blog_project/blog/views.py", line 31, in index
    return render(request, 'index.html', locals())
  File "/home/ubunturoot/.pyenv/versions/blog/lib/python3.5/site-packages/django/shortcuts.py", line 30, in render
    content = loader.render_to_string(template_name, context, request, using=using)
  File "/home/ubunturoot/.pyenv/versions/blog/lib/python3.5/site-packages/django/template/loader.py", line 68, in render_to_string
    return template.render(context, request)
  File "/home/ubunturoot/.pyenv/versions/blog/lib/python3.5/site-packages/django/template/backends/django.py", line 66, in render
    return self.template.render(context)
  File "/home/ubunturoot/.pyenv/versions/blog/lib/python3.5/site-packages/django/template/base.py", line 207, in render
    return self._render(context)
  File "/home/ubunturoot/.pyenv/versions/blog/lib/python3.5/site-packages/django/template/base.py", line 199, in _render
    return self.nodelist.render(context)
  File "/home/ubunturoot/.pyenv/versions/blog/lib/python3.5/site-packages/django/template/base.py", line 990, in render
    bit = node.render_annotated(context)
  File "/home/ubunturoot/.pyenv/versions/blog/lib/python3.5/site-packages/django/template/base.py", line 957, in render_annotated
    return self.render(context)
  File "/home/ubunturoot/.pyenv/versions/blog/lib/python3.5/site-packages/django/template/loader_tags.py", line 177, in render
    return compiled_parent._render(context)
  File "/home/ubunturoot/.pyenv/versions/blog/lib/python3.5/site-packages/django/template/base.py", line 199, in _render
    return self.nodelist.render(context)
  File "/home/ubunturoot/.pyenv/versions/blog/lib/python3.5/site-packages/django/template/base.py", line 990, in render
    bit = node.render_annotated(context)
  File "/home/ubunturoot/.pyenv/versions/blog/lib/python3.5/site-packages/django/template/base.py", line 957, in render_annotated
    return self.render(context)
  File "/home/ubunturoot/.pyenv/versions/blog/lib/python3.5/site-packages/django/template/defaulttags.py", line 216, in render
    nodelist.append(node.render_annotated(context))
  File "/home/ubunturoot/.pyenv/versions/blog/lib/python3.5/site-packages/django/template/base.py", line 957, in render_annotated
    return self.render(context)
  File "/home/ubunturoot/.pyenv/versions/blog/lib/python3.5/site-packages/django/template/defaulttags.py", line 458, in render
    url = reverse(view_name, args=args, kwargs=kwargs, current_app=current_app)
  File "/home/ubunturoot/.pyenv/versions/blog/lib/python3.5/site-packages/django/urls/base.py", line 91, in reverse
    return force_text(iri_to_uri(resolver._reverse_with_prefix(view, prefix, *args, **kwargs)))
  File "/home/ubunturoot/.pyenv/versions/blog/lib/python3.5/site-packages/django/urls/resolvers.py", line 497, in _reverse_with_prefix
    raise NoReverseMatch(msg)
django.urls.exceptions.NoReverseMatch: Reverse for 'category' with no arguments not found. 1 pattern(s) tried: ['$category/$']
2017-05-10 15:53:17,071 [Thread-6:-1274021056] [django.request:135] [exception:handle_uncaught_exception] [ERROR]- Internal Server Error: /
Traceback (most recent call last):
  File "/home/ubunturoot/.pyenv/versions/blog/lib/python3.5/site-packages/django/core/handlers/exception.py", line 41, in inner
    response = get_response(request)
  File "/home/ubunturoot/.pyenv/versions/blog/lib/python3.5/site-packages/django/core/handlers/base.py", line 187, in _get_response
    response = self.process_exception_by_middleware(e, request)
  File "/home/ubunturoot/.pyenv/versions/blog/lib/python3.5/site-packages/django/core/handlers/base.py", line 185, in _get_response
    response = wrapped_callback(request, *callback_args, **callback_kwargs)
  File "/home/ubunturoot/blog/blog_project/blog/views.py", line 31, in index
    return render(request, 'index.html', locals())
  File "/home/ubunturoot/.pyenv/versions/blog/lib/python3.5/site-packages/django/shortcuts.py", line 30, in render
    content = loader.render_to_string(template_name, context, request, using=using)
  File "/home/ubunturoot/.pyenv/versions/blog/lib/python3.5/site-packages/django/template/loader.py", line 68, in render_to_string
    return template.render(context, request)
  File "/home/ubunturoot/.pyenv/versions/blog/lib/python3.5/site-packages/django/template/backends/django.py", line 66, in render
    return self.template.render(context)
  File "/home/ubunturoot/.pyenv/versions/blog/lib/python3.5/site-packages/django/template/base.py", line 207, in render
    return self._render(context)
  File "/home/ubunturoot/.pyenv/versions/blog/lib/python3.5/site-packages/django/template/base.py", line 199, in _render
    return self.nodelist.render(context)
  File "/home/ubunturoot/.pyenv/versions/blog/lib/python3.5/site-packages/django/template/base.py", line 990, in render
    bit = node.render_annotated(context)
  File "/home/ubunturoot/.pyenv/versions/blog/lib/python3.5/site-packages/django/template/base.py", line 957, in render_annotated
    return self.render(context)
  File "/home/ubunturoot/.pyenv/versions/blog/lib/python3.5/site-packages/django/template/loader_tags.py", line 177, in render
    return compiled_parent._render(context)
  File "/home/ubunturoot/.pyenv/versions/blog/lib/python3.5/site-packages/django/template/base.py", line 199, in _render
    return self.nodelist.render(context)
  File "/home/ubunturoot/.pyenv/versions/blog/lib/python3.5/site-packages/django/template/base.py", line 990, in render
    bit = node.render_annotated(context)
  File "/home/ubunturoot/.pyenv/versions/blog/lib/python3.5/site-packages/django/template/base.py", line 957, in render_annotated
    return self.render(context)
  File "/home/ubunturoot/.pyenv/versions/blog/lib/python3.5/site-packages/django/template/defaulttags.py", line 216, in render
    nodelist.append(node.render_annotated(context))
  File "/home/ubunturoot/.pyenv/versions/blog/lib/python3.5/site-packages/django/template/base.py", line 957, in render_annotated
    return self.render(context)
  File "/home/ubunturoot/.pyenv/versions/blog/lib/python3.5/site-packages/django/template/defaulttags.py", line 458, in render
    url = reverse(view_name, args=args, kwargs=kwargs, current_app=current_app)
  File "/home/ubunturoot/.pyenv/versions/blog/lib/python3.5/site-packages/django/urls/base.py", line 91, in reverse
    return force_text(iri_to_uri(resolver._reverse_with_prefix(view, prefix, *args, **kwargs)))
  File "/home/ubunturoot/.pyenv/versions/blog/lib/python3.5/site-packages/django/urls/resolvers.py", line 497, in _reverse_with_prefix
    raise NoReverseMatch(msg)
django.urls.exceptions.NoReverseMatch: Reverse for 'category' with no arguments not found. 1 pattern(s) tried: ['$category/$']
2017-05-10 15:56:31,691 [Thread-8:-1250952384] [django.request:152] [base:get_response] [WARNING]- Not Found: /category
2017-05-10 15:56:40,031 [Thread-9:-1274021056] [django.request:152] [base:get_response] [WARNING]- Not Found: /category、
2017-05-10 15:56:44,134 [Thread-14:-1299199168] [django.request:152] [base:get_response] [WARNING]- Not Found: /category/
2017-05-10 15:57:49,746 [Thread-2:-1250690240] [django.request:152] [base:get_response] [WARNING]- Not Found: /category/
2017-05-10 15:57:51,055 [Thread-3:-1260389568] [django.request:152] [base:get_response] [WARNING]- Not Found: /category/
2017-05-10 15:57:59,766 [Thread-4:-1270875328] [django.request:135] [exception:handle_uncaught_exception] [ERROR]- Internal Server Error: /
Traceback (most recent call last):
  File "/home/ubunturoot/.pyenv/versions/blog/lib/python3.5/site-packages/django/core/handlers/exception.py", line 41, in inner
    response = get_response(request)
  File "/home/ubunturoot/.pyenv/versions/blog/lib/python3.5/site-packages/django/core/handlers/base.py", line 187, in _get_response
    response = self.process_exception_by_middleware(e, request)
  File "/home/ubunturoot/.pyenv/versions/blog/lib/python3.5/site-packages/django/core/handlers/base.py", line 185, in _get_response
    response = wrapped_callback(request, *callback_args, **callback_kwargs)
  File "/home/ubunturoot/blog/blog_project/blog/views.py", line 31, in index
    return render(request, 'index.html', locals())
  File "/home/ubunturoot/.pyenv/versions/blog/lib/python3.5/site-packages/django/shortcuts.py", line 30, in render
    content = loader.render_to_string(template_name, context, request, using=using)
  File "/home/ubunturoot/.pyenv/versions/blog/lib/python3.5/site-packages/django/template/loader.py", line 68, in render_to_string
    return template.render(context, request)
  File "/home/ubunturoot/.pyenv/versions/blog/lib/python3.5/site-packages/django/template/backends/django.py", line 66, in render
    return self.template.render(context)
  File "/home/ubunturoot/.pyenv/versions/blog/lib/python3.5/site-packages/django/template/base.py", line 207, in render
    return self._render(context)
  File "/home/ubunturoot/.pyenv/versions/blog/lib/python3.5/site-packages/django/template/base.py", line 199, in _render
    return self.nodelist.render(context)
  File "/home/ubunturoot/.pyenv/versions/blog/lib/python3.5/site-packages/django/template/base.py", line 990, in render
    bit = node.render_annotated(context)
  File "/home/ubunturoot/.pyenv/versions/blog/lib/python3.5/site-packages/django/template/base.py", line 957, in render_annotated
    return self.render(context)
  File "/home/ubunturoot/.pyenv/versions/blog/lib/python3.5/site-packages/django/template/loader_tags.py", line 177, in render
    return compiled_parent._render(context)
  File "/home/ubunturoot/.pyenv/versions/blog/lib/python3.5/site-packages/django/template/base.py", line 199, in _render
    return self.nodelist.render(context)
  File "/home/ubunturoot/.pyenv/versions/blog/lib/python3.5/site-packages/django/template/base.py", line 990, in render
    bit = node.render_annotated(context)
  File "/home/ubunturoot/.pyenv/versions/blog/lib/python3.5/site-packages/django/template/base.py", line 957, in render_annotated
    return self.render(context)
  File "/home/ubunturoot/.pyenv/versions/blog/lib/python3.5/site-packages/django/template/defaulttags.py", line 216, in render
    nodelist.append(node.render_annotated(context))
  File "/home/ubunturoot/.pyenv/versions/blog/lib/python3.5/site-packages/django/template/base.py", line 957, in render_annotated
    return self.render(context)
  File "/home/ubunturoot/.pyenv/versions/blog/lib/python3.5/site-packages/django/template/defaulttags.py", line 458, in render
    url = reverse(view_name, args=args, kwargs=kwargs, current_app=current_app)
  File "/home/ubunturoot/.pyenv/versions/blog/lib/python3.5/site-packages/django/urls/base.py", line 91, in reverse
    return force_text(iri_to_uri(resolver._reverse_with_prefix(view, prefix, *args, **kwargs)))
  File "/home/ubunturoot/.pyenv/versions/blog/lib/python3.5/site-packages/django/urls/resolvers.py", line 497, in _reverse_with_prefix
    raise NoReverseMatch(msg)
django.urls.exceptions.NoReverseMatch: Reverse for 'category' with no arguments not found. 1 pattern(s) tried: ['$category/$']
